Workbook

Sheet CCMFUT_F_0_Diário
A1: Ativo | B1: Data | C1: Abertura | D1: Máximo | E1: Mínimo | F1: Fechamento | G1: Volume | H1: Quantidade
A2: CCMFUT | B2: 45491 | C2: 64.1 | D2: 64.11 | E2: 63.09 | F2: 63.13 | G2: 3.2358064e+08 | H2: 11326
A3: CCMFUT | B3: 45492 | C3: 63.12 | D3: 64.41 | E3: 62.86 | F3: 64.1 | G3: 1.897695e+08 | H3: 6605
A4: CCMFUT | B4: 45495 | C4: 64.1 | D4: 65.68 | E4: 64.07 | F4: 65.5 | G4: 3.6491803e+08 | H4: 12435
A5: CCMFUT | B5: 45496 | C5: 65.54 | D5: 66.55 | E5: 65.06 | F5: 66 | G5: 287140757 | H5: 9649
A6: CCMFUT | B6: 45497 | C6: 66.01 | D6: 67.2 | E6: 65.63 | F6: 66.85 | G6: 3.1637827e+08 | H6: 10550
A7: CCMFUT | B7: 45498 | C7: 66.92 | D7: 67.74 | E7: 66.23 | F7: 66.54 | G7: 3.9628475e+08 | H7: 13132
A8: CCMFUT | B8: 45499 | C8: 66.65 | D8: 66.66 | E8: 65.71 | F8: 66.2 | G8: 3.4992707e+08 | H8: 11747
A9: CCMFUT | B9: 45502 | C9: 66.23 | D9: 66.66 | E9: 65.68 | F9: 66.19 | G9: 2.0303791e+08 | H9: 6829
A10: CCMFUT | B10: 45503 | C10: 66.1 | D10: 66.16 | E10: 65.01 | F10: 65.06 | G10: 2.3114475e+08 | H10: 7845
A11: CCMFUT | B11: 45504 | C11: 65.01 | D11: 65.3 | E11: 64.41 | F11: 64.63 | G11: 3.0427848e+08 | H11: 10448
A12: CCMFUT | B12: 45505 | C12: 64.63 | D12: 65.77 | E12: 64.6 | F12: 65.68 | G12: 2.2201019e+08 | H12: 7554
A13: CCMFUT | B13: 45506 | C13: 65.9 | D13: 67.09 | E13: 65.65 | F13: 67.01 | G13: 2.312423e+08 | H13: 7733
... A500: CCMFUT | B500: 46220 | C500: 68.43 | D500: 68.95 | E500: 68.2 | F500: 68.8 | G500: 1.1691403e+08 | H500: 3786

Sheet Análise_Variação
A1: ANÁLISE DIÁRIA | G1: ANÁLISE SEMANAL | M1: ANÁLISE MENSAL | S1: RESUMO ESTATÍSTICO - DIÁRIO | V1: COMPARATIVO DE BANDAS DE DESVIO PADRÃO
A2: Data | B2: Fechamento | C2: Var % | D2: Máximo Acum | E2: Drawdown % | G2: Semana | H2: Fech. Semana | I2: Var % | J2: Máximo Acum | K2: Drawdown % | M2: Mês | N2: Fech. Mês | O2: Var % | P2: Máximo Acum | Q2: Drawdown % | S2: Métrica | T2: Valor | V2: Banda | W2: Diário | X2: Semanal | Y2: Mensal
A3: =CCMFUT_F_0_Diário!B2 -> 45491 | B3: =CCMFUT_F_0_Diário!F2 -> 63.13 | C3: =0 -> 0 | D3: =B3 -> 63.13 | E3: =0 -> 0 | G3: 2024-S29 | H3: 64.1 | I3: =0 -> 0 | J3: =H3 -> 64.1 | K3: =0 -> 0 | M3: 45474 | N3: 65.68 | O3: =0 -> 0 | P3: =N3 -> 65.68 | Q3: =0 -> 0 | S3: Média Variação | T3: =AVERAGE(C4:C501) -> 0.00022604587 | V3: Média - 3σ | W3: =T9 -> -0.030800031 | X3: =T22 -> -0.062791209 | Y3: =T35 -> -0.15759924
A4: =CCMFUT_F_0_Diário!B3 -> 45492 | B4: =CCMFUT_F_0_Diário!F3 -> 64.1 | C4: =(B4-B3)/B3 -> 0.01536512 | D4: =MAX($B$3:B4) -> 64.1 | E4: =(B4-D4)/D4 -> 0 | G4: 2024-S30 | H4: 66.2 | I4: =(H4-H3)/H3 -> 0.03276131 | J4: =MAX($H$3:H4) -> 66.2 | K4: =(H4-J4)/J4 -> 0 | M4: Ago/2024 | N4: 66.87 | O4: =(N4-N3)/N3 -> 0.018118149 | P4: =MAX($N$3:N4) -> 66.87 | Q4: =(N4-P4)/P4 -> 0 | S4: Desvio Padrão (σ) | T4: =_xlfn.STDEV.S(C4:C501) -> 0.010342026 | V4: Média - 2σ | W4: =T7 -> -0.020458005 | X4: =T20 -> -0.041563993 | Y4: =T33 -> -0.10397492
A5: =CCMFUT_F_0_Diário!B4 -> 45495 | B5: =CCMFUT_F_0_Diário!F4 -> 65.5 | C5: =(B5-B4)/B4 -> 0.021840874 | D5: =MAX($B$3:B5) -> 65.5 | E5: =(B5-D5)/D5 -> 0 | G5: 2024-S31 | H5: 67.01 | I5: =(H5-H4)/H4 -> 0.01223565 | J5: =MAX($H$3:H5) -> 67.01 | K5: =(H5-J5)/J5 -> 0 | M5: Set/2024 | N5: 71.3 | O5: =(N5-N4)/N4 -> 0.066247944 | P5: =MAX($N$3:N5) -> 71.3 | Q5: =(N5-P5)/P5 -> 0 | S5: Média - 1σ | T5: =T3-T4 -> -0.01011598 | V5: Média - 1σ | W5: =T5 -> -0.01011598 | X5: =T18 -> -0.020336777 | Y5: =T31 -> -0.050350599
A6: =CCMFUT_F_0_Diário!B5 -> 45496 | B6: =CCMFUT_F_0_Diário!F5 -> 66 | C6: =(B6-B5)/B5 -> 0.0076335878 | D6: =MAX($B$3:B6) -> 66 | E6: =(B6-D6)/D6 -> 0 | G6: 2024-S32 | H6: 65.28 | I6: =(H6-H5)/H5 -> -0.025817042 | J6: =MAX($H$3:H6) -> 67.01 | K6: =(H6-J6)/J6 -> -0.025817042 | M6: Out/2024 | N6: 75.48 | O6: =(N6-N5)/N5 -> 0.058625526 | P6: =MAX($N$3:N6) -> 75.48 | Q6: =(N6-P6)/P6 -> 0 | S6: Média + 1σ | T6: =T3+T4 -> 0.010568071 | V6: Média | W6: =T3 -> 0.00022604587 | X6: =T16 -> 0.0008904387 | Y6: =T29 -> 0.0032737215
A7: =CCMFUT_F_0_Diário!B6 -> 45497 | B7: =CCMFUT_F_0_Diário!F6 -> 66.85 | C7: =(B7-B6)/B6 -> 0.012878788 | D7: =MAX($B$3:B7) -> 66.85 | E7: =(B7-D7)/D7 -> 0 | G7: 2024-S33 | H7: 64.55 | I7: =(H7-H6)/H6 -> -0.011182598 | J7: =MAX($H$3:H7) -> 67.01 | K7: =(H7-J7)/J7 -> -0.036710939 | M7: 45597 | N7: 72.62 | O7: =(N7-N6)/N6 -> -0.037890832 | P7: =MAX($N$3:N7) -> 75.48 | Q7: =(N7-P7)/P7 -> -0.037890832 | S7: Média - 2σ | T7: =T3-2*T4 -> -0.020458005 | V7: Média + 1σ | W7: =T6 -> 0.010568071 | X7: =T19 -> 0.022117655 | Y7: =T32 -> 0.056898042
A8: =CCMFUT_F_0_Diário!B7 -> 45498 | B8: =CCMFUT_F_0_Diário!F7 -> 66.54 | C8: =(B8-B7)/B7 -> -0.0046372476 | D8: =MAX($B$3:B8) -> 66.85 | E8: =(B8-D8)/D8 -> -0.0046372476 | G8: 2024-S34 | H8: 65.28 | I8: =(H8-H7)/H7 -> 0.011309063 | J8: =MAX($H$3:H8) -> 67.01 | K8: =(H8-J8)/J8 -> -0.025817042 | M8: Dez/2024 | N8: 74.69 | O8: =(N8-N7)/N7 -> 0.028504544 | P8: =MAX($N$3:N8) -> 75.48 | Q8: =(N8-P8)/P8 -> -0.010466349 | S8: Média + 2σ | T8: =T3+2*T4 -> 0.020910097 | V8: Média + 2σ | W8: =T8 -> 0.020910097 | X8: =T21 -> 0.04334487 | Y8: =T34 -> 0.11052236
A9: =CCMFUT_F_0_Diário!B8 -> 45499 | B9: =CCMFUT_F_0_Diário!F8 -> 66.2 | C9: =(B9-B8)/B8 -> -0.0051097084 | D9: =MAX($B$3:B9) -> 66.85 | E9: =(B9-D9)/D9 -> -0.009723261 | G9: 2024-S35 | H9: 66.87 | I9: =(H9-H8)/H8 -> 0.024356618 | J9: =MAX($H$3:H9) -> 67.01 | K9: =(H9-J9)/J9 -> -0.0020892404 | M9: 45658 | N9: 74.48 | O9: =(N9-N8)/N8 -> -0.0028116214 | P9: =MAX($N$3:N9) -> 75.48 | Q9: =(N9-P9)/P9 -> -0.013248543 | S9: Média - 3σ | T9: =T3-3*T4 -> -0.030800031 | V9: Média + 3σ | W9: =T10 -> 0.031252123 | X9: =T23 -> 0.064572086 | Y9: =T36 -> 0.16414668
A10: =CCMFUT_F_0_Diário!B9 -> 45502 | B10: =CCMFUT_F_0_Diário!F9 -> 66.19 | C10: =(B10-B9)/B9 -> -0.0001510574 | D10: =MAX($B$3:B10) -> 66.85 | E10: =(B10-D10)/D10 -> -0.0098728497 | G10: 2024-S36 | H10: 68.27 | I10: =(H10-H9)/H9 -> 0.020936145 | J10: =MAX($H$3:H10) -> 68.27 | K10: =(H10-J10)/J10 -> 0 | M10: Fev/2025 | N10: 85.48 | O10: =(N10-N9)/N9 -> 0.14769066 | P10: =MAX($N$3:N10) -> 85.48 | Q10: =(N10-P10)/P10 -> 0 | S10: Média + 3σ | T10: =T3+3*T4 -> 0.031252123
A11: =CCMFUT_F_0_Diário!B10 -> 45503 | B11: =CCMFUT_F_0_Diário!F10 -> 65.06 | C11: =(B11-B10)/B10 -> -0.017072065 | D11: =MAX($B$3:B11) -> 66.85 | E11: =(B11-D11)/D11 -> -0.026776365 | G11: 2024-S37 | H11: 70.06 | I11: =(H11-H10)/H10 -> 0.026219423 | J11: =MAX($H$3:H11) -> 70.06 | K11: =(H11-J11)/J11 -> 0 | M11: 45717 | N11: 85.21 | O11: =(N11-N10)/N10 -> -0.0031586336 | P11: =MAX($N$3:N11) -> 85.48 | Q11: =(N11-P11)/P11 -> -0.0031586336 | S11: Drawdown Máximo | T11: =MIN(E3:E501) -> -0.2742957
A12: =CCMFUT_F_0_Diário!B11 -> 45504 | B12: =CCMFUT_F_0_Diário!F11 -> 64.63 | C12: =(B12-B11)/B11 -> -0.0066092837 | D12: =MAX($B$3:B12) -> 66.85 | E12: =(B12-D12)/D12 -> -0.033208676 | G12: 2024-S38 | H12: 70.11 | I12: =(H12-H11)/H11 -> 0.00071367399 | J12: =MAX($H$3:H12) -> 70.11 | K12: =(H12-J12)/J12 -> 0 | M12: Abr/2025 | N12: 82.39 | O12: =(N12-N11)/N11 -> -0.033094707 | P12: =MAX($N$3:N12) -> 85.48 | Q12: =(N12-P12)/P12 -> -0.036148807 | S12: Drawdown Médio | T12: =AVERAGE(E3:E501) -> -0.11457431
A13: =CCMFUT_F_0_Diário!B12 -> 45505 | B13: =CCMFUT_F_0_Diário!F12 -> 65.68 | C13: =(B13-B12)/B12 -> 0.016246325 | D13: =MAX($B$3:B13) -> 66.85 | E13: =(B13-D13)/D13 -> -0.01750187 | G13: 2024-S39 | H13: 70.99 | I13: =(H13-H12)/H12 -> 0.012551704 | J13: =MAX($H$3:H13) -> 70.99 | K13: =(H13-J13)/J13 -> 0 | M13: Mai/2025 | N13: 78.77 | O13: =(N13-N12)/N12 -> -0.043937371 | P13: =MAX($N$3:N13) -> 85.48 | Q13: =(N13-P13)/P13 -> -0.078497894
A14: =CCMFUT_F_0_Diário!B13 -> 45506 | B14: =CCMFUT_F_0_Diário!F13 -> 67.01 | C14: =(B14-B13)/B13 -> 0.020249695 | D14: =MAX($B$3:B14) -> 67.01 | E14: =(B14-D14)/D14 -> 0 | G14: 2024-S40 | H14: 70.28 | I14: =(H14-H13)/H13 -> -0.010001409 | J14: =MAX($H$3:H14) -> 70.99 | K14: =(H14-J14)/J14 -> -0.010001409 | M14: 45809 | N14: 75.33 | O14: =(N14-N13)/N13 -> -0.043671449 | P14: =MAX($N$3:N14) -> 85.48 | Q14: =(N14-P14)/P14 -> -0.11874123 | S14: RESUMO ESTATÍSTICO - SEMANAL
A15: =CCMFUT_F_0_Diário!B14 -> 45509 | B15: =CCMFUT_F_0_Diário!F14 -> 66.87 | C15: =(B15-B14)/B14 -> -0.0020892404 | D15: =MAX($B$3:B15) -> 67.01 | E15: =(B15-D15)/D15 -> -0.0020892404 | G15: 2024-S41 | H15: 70.78 | I15: =(H15-H14)/H14 -> 0.0071143995 | J15: =MAX($H$3:H15) -> 70.99 | K15: =(H15-J15)/J15 -> -0.0029581631 | M15: 45839 | N15: 81.91 | O15: =(N15-N14)/N14 -> 0.087348998 | P15: =MAX($N$3:N15) -> 85.48 | Q15: =(N15-P15)/P15 -> -0.041764155 | S15: Métrica | T15: Valor
A16: =CCMFUT_F_0_Diário!B15 -> 45510 | B16: =CCMFUT_F_0_Diário!F15 -> 65.38 | C16: =(B16-B15)/B15 -> -0.02228204 | D16: =MAX($B$3:B16) -> 67.01 | E16: =(B16-D16)/D16 -> -0.024324728 | G16: 2024-S42 | H16: 71.56 | I16: =(H16-H15)/H15 -> 0.011020062 | J16: =MAX($H$3:H16) -> 71.56 | K16: =(H16-J16)/J16 -> 0 | M16: Ago/2025 | N16: 79.48 | O16: =(N16-N15)/N15 -> -0.029666707 | P16: =MAX($N$3:N16) -> 85.48 | Q16: =(N16-P16)/P16 -> -0.070191858 | S16: Média Variação | T16: =AVERAGE(I4:I109) -> 0.0008904387
A17: =CCMFUT_F_0_Diário!B16 -> 45511 | B17: =CCMFUT_F_0_Diário!F16 -> 65.15 | C17: =(B17-B16)/B16 -> -0.0035178954 | D17: =MAX($B$3:B17) -> 67.01 | E17: =(B17-D17)/D17 -> -0.027757051 | G17: 2024-S43 | H17: 74.97 | I17: =(H17-H16)/H16 -> 0.04765232 | J17: =MAX($H$3:H17) -> 74.97 | K17: =(H17-J17)/J17 -> 0 | M17: Set/2025 | N17: 76.32 | O17: =(N17-N16)/N16 -> -0.03975843 | P17: =MAX($N$3:N17) -> 85.48 | Q17: =(N17-P17)/P17 -> -0.10715957 | S17: Desvio Padrão (σ) | T17: =_xlfn.STDEV.S(I4:I109) -> 0.021227216
A18: =CCMFUT_F_0_Diário!B17 -> 45512 | B18: =CCMFUT_F_0_Diário!F17 -> 65.13 | C18: =(B18-B17)/B17 -> -0.00030698388 | D18: =MAX($B$3:B18) -> 67.01 | E18: =(B18-D18)/D18 -> -0.028055514 | G18: 2024-S44 | H18: 75.48 | I18: =(H18-H17)/H17 -> 0.0068027211 | J18: =MAX($H$3:H18) -> 75.48 | K18: =(H18-J18)/J18 -> 0 | M18: Out/2025 | N18: 79.21 | O18: =(N18-N17)/N17 -> 0.037866876 | P18: =MAX($N$3:N18) -> 85.48 | Q18: =(N18-P18)/P18 -> -0.073350491 | S18: Média - 1σ | T18: =T16-T17 -> -0.020336777
A19: =CCMFUT_F_0_Diário!B18 -> 45513 | B19: =CCMFUT_F_0_Diário!F18 -> 65.28 | C19: =(B19-B18)/B18 -> 0.0023030861 | D19: =MAX($B$3:B19) -> 67.01 | E19: =(B19-D19)/D19 -> -0.025817042 | G19: 2024-S45 | H19: 76.33 | I19: =(H19-H18)/H18 -> 0.011261261 | J19: =MAX($H$3:H19) -> 76.33 | K19: =(H19-J19)/J19 -> 0 | M19: 45962 | N19: 83.12 | O19: =(N19-N18)/N18 -> 0.049362454 | P19: =MAX($N$3:N19) -> 85.48 | Q19: =(N19-P19)/P19 -> -0.027608797 | S19: Média + 1σ | T19: =T16+T17 -> 0.022117655
A20: =CCMFUT_F_0_Diário!B19 -> 45516 | B20: =CCMFUT_F_0_Diário!F19 -> 65.54 | C20: =(B20-B19)/B19 -> 0.0039828431 | D20: =MAX($B$3:B20) -> 67.01 | E20: =(B20-D20)/D20 -> -0.021937024 | G20: 2024-S46 | H20: 75.53 | I20: =(H20-H19)/H19 -> -0.010480807 | J20: =MAX($H$3:H20) -> 76.33 | K20: =(H20-J20)/J20 -> -0.010480807 | M20: Dez/2025 | N20: 78.66 | O20: =(N20-N19)/N19 -> -0.053657363 | P20: =MAX($N$3:N20) -> 85.48 | Q20: =(N20-P20)/P20 -> -0.079784745 | S20: Média - 2σ | T20: =T16-2*T17 -> -0.041563993
A21: =CCMFUT_F_0_Diário!B20 -> 45517 | B21: =CCMFUT_F_0_Diário!F20 -> 64.98 | C21: =(B21-B20)/B20 -> -0.0085444004 | D21: =MAX($B$3:B21) -> 67.01 | E21: =(B21-D21)/D21 -> -0.030293986 | G21: 2024-S47 | H21: 73.09 | I21: =(H21-H20)/H20 -> -0.032305044 | J21: =MAX($H$3:H21) -> 76.33 | K21: =(H21-J21)/J21 -> -0.042447268 | M21: 46023 | N21: 72.81 | O21: =(N21-N20)/N20 -> -0.074370709 | P21: =MAX($N$3:N21) -> 85.48 | Q21: =(N21-P21)/P21 -> -0.14822181 | S21: Média + 2σ | T21: =T16+2*T17 -> 0.04334487
A22: =CCMFUT_F_0_Diário!B21 -> 45518 | B22: =CCMFUT_F_0_Diário!F21 -> 64.73 | C22: =(B22-B21)/B21 -> -0.0038473376 | D22: =MAX($B$3:B22) -> 67.01 | E22: =(B22-D22)/D22 -> -0.034024772 | G22: 2024-S48 | H22: 72.62 | I22: =(H22-H21)/H21 -> -0.0064304282 | J22: =MAX($H$3:H22) -> 76.33 | K22: =(H22-J22)/J22 -> -0.048604743 | M22: Fev/2026 | N22: 76.1 | O22: =(N22-N21)/N21 -> 0.045186101 | P22: =MAX($N$3:N22) -> 85.48 | Q22: =(N22-P22)/P22 -> -0.10973327 | S22: Média - 3σ | T22: =T16-3*T17 -> -0.062791209
A23: =CCMFUT_F_0_Diário!B22 -> 45519 | B23: =CCMFUT_F_0_Diário!F22 -> 65.32 | C23: =(B23-B22)/B22 -> 0.0091147845 | D23: =MAX($B$3:B23) -> 67.01 | E23: =(B23-D23)/D23 -> -0.025220116 | G23: 2024-S49 | H23: 74.95 | I23: =(H23-H22)/H22 -> 0.032084825 | J23: =MAX($H$3:H23) -> 76.33 | K23: =(H23-J23)/J23 -> -0.018079392 | M23: 46082 | N23: 73.77 | O23: =(N23-N22)/N22 -> -0.030617608 | P23: =MAX($N$3:N23) -> 85.48 | Q23: =(N23-P23)/P23 -> -0.13699111 | S23: Média + 3σ | T23: =T16+3*T17 -> 0.064572086
A24: =CCMFUT_F_0_Diário!B23 -> 45520 | B24: =CCMFUT_F_0_Diário!F23 -> 64.55 | C24: =(B24-B23)/B23 -> -0.01178812 | D24: =MAX($B$3:B24) -> 67.01 | E24: =(B24-D24)/D24 -> -0.036710939 | G24: 2024-S50 | H24: 75.49 | I24: =(H24-H23)/H23 -> 0.0072048032 | J24: =MAX($H$3:H24) -> 76.33 | K24: =(H24-J24)/J24 -> -0.011004847 | M24: Abr/2026 | N24: 71.6 | O24: =(N24-N23)/N23 -> -0.029415752 | P24: =MAX($N$3:N24) -> 85.48 | Q24: =(N24-P24)/P24 -> -0.16237716 | S24: Drawdown Máximo | T24: =MIN(K3:K109) -> -0.22810261
A25: =CCMFUT_F_0_Diário!B24 -> 45523 | B25: =CCMFUT_F_0_Diário!F24 -> 65.18 | C25: =(B25-B24)/B24 -> 0.0097598761 | D25: =MAX($B$3:B25) -> 67.01 | E25: =(B25-D25)/D25 -> -0.027309357 | G25: 2024-S51 | H25: 74.34 | I25: =(H25-H24)/H24 -> -0.015233806 | J25: =MAX($H$3:H25) -> 76.33 | K25: =(H25-J25)/J25 -> -0.026071007 | M25: Mai/2026 | N25: 67.75 | O25: =(N25-N24)/N24 -> -0.05377095 | P25: =MAX($N$3:N25) -> 85.48 | Q25: =(N25-P25)/P25 -> -0.20741694 | S25: Drawdown Médio | T25: =AVERAGE(K3:K109) -> -0.079455482
A26: =CCMFUT_F_0_Diário!B25 -> 45524 | B26: =CCMFUT_F_0_Diário!F25 -> 65.54 | C26: =(B26-B25)/B25 -> 0.0055231666 | D26: =MAX($B$3:B26) -> 67.01 | E26: =(B26-D26)/D26 -> -0.021937024 | G26: 2024-S52 | H26: 74.2 | I26: =(H26-H25)/H25 -> -0.0018832392 | J26: =MAX($H$3:H26) -> 76.33 | K26: =(H26-J26)/J26 -> -0.027905149 | M26: 46174 | N26: 68.36 | O26: =(N26-N25)/N25 -> 0.00900369 | P26: =MAX($N$3:N26) -> 85.48 | Q26: =(N26-P26)/P26 -> -0.20028077
A27: =CCMFUT_F_0_Diário!B26 -> 45525 | B27: =CCMFUT_F_0_Diário!F26 -> 65.24 | C27: =(B27-B26)/B26 -> -0.0045773573 | D27: =MAX($B$3:B27) -> 67.01 | E27: =(B27-D27)/D27 -> -0.026413968 | G27: 2024-S53 | H27: 74.69 | I27: =(H27-H26)/H26 -> 0.0066037736 | J27: =MAX($H$3:H27) -> 76.33 | K27: =(H27-J27)/J27 -> -0.021485654 | M27: 46204 | N27: 68.8 | O27: =(N27-N26)/N26 -> 0.0064365126 | P27: =MAX($N$3:N27) -> 85.48 | Q27: =(N27-P27)/P27 -> -0.19513336 | S27: RESUMO ESTATÍSTICO - MENSAL
A28: =CCMFUT_F_0_Diário!B27 -> 45526 | B28: =CCMFUT_F_0_Diário!F27 -> 65.55 | C28: =(B28-B27)/B27 -> 0.0047516861 | D28: =MAX($B$3:B28) -> 67.01 | E28: =(B28-D28)/D28 -> -0.021787793 | G28: 2025-S01 | H28: 73.73 | I28: =(H28-H27)/H27 -> -0.012853126 | J28: =MAX($H$3:H28) -> 76.33 | K28: =(H28-J28)/J28 -> -0.034062623 | S28: Métrica | T28: Valor
A29: =CCMFUT_F_0_Diário!B28 -> 45527 | B29: =CCMFUT_F_0_Diário!F28 -> 65.28 | C29: =(B29-B28)/B28 -> -0.0041189931 | D29: =MAX($B$3:B29) -> 67.01 | E29: =(B29-D29)/D29 -> -0.025817042 | G29: 2025-S02 | H29: 76.9 | I29: =(H29-H28)/H28 -> 0.04299471 | J29: =MAX($H$3:H29) -> 76.9 | K29: =(H29-J29)/J29 -> 0 | S29: Média Variação | T29: =AVERAGE(O4:O27) -> 0.0032737215
A30: =CCMFUT_F_0_Diário!B29 -> 45530 | B30: =CCMFUT_F_0_Diário!F29 -> 65.13 | C30: =(B30-B29)/B29 -> -0.0022977941 | D30: =MAX($B$3:B30) -> 67.01 | E30: =(B30-D30)/D30 -> -0.028055514 | G30: 2025-S03 | H30: 75.67 | I30: =(H30-H29)/H29 -> -0.015994798 | J30: =MAX($H$3:H30) -> 76.9 | K30: =(H30-J30)/J30 -> -0.015994798 | S30: Desvio Padrão (σ) | T30: =_xlfn.STDEV.S(O4:O27) -> 0.053624321
A31: =CCMFUT_F_0_Diário!B30 -> 45531 | B31: =CCMFUT_F_0_Diário!F30 -> 65.52 | C31: =(B31-B30)/B30 -> 0.005988024 | D31: =MAX($B$3:B31) -> 67.01 | E31: =(B31-D31)/D31 -> -0.022235487 | G31: 2025-S04 | H31: 74.14 | I31: =(H31-H30)/H30 -> -0.020219374 | J31: =MAX($H$3:H31) -> 76.9 | K31: =(H31-J31)/J31 -> -0.035890767 | S31: Média - 1σ | T31: =T29-T30 -> -0.050350599
A32: =CCMFUT_F_0_Diário!B31 -> 45532 | B32: =CCMFUT_F_0_Diário!F31 -> 65.52 | C32: =(B32-B31)/B31 -> 0 | D32: =MAX($B$3:B32) -> 67.01 | E32: =(B32-D32)/D32 -> -0.022235487 | G32: 2025-S05 | H32: 74.48 | I32: =(H32-H31)/H31 -> 0.0045859185 | J32: =MAX($H$3:H32) -> 76.9 | K32: =(H32-J32)/J32 -> -0.031469441 | S32: Média + 1σ | T32: =T29+T30 -> 0.056898042
A33: =CCMFUT_F_0_Diário!B32 -> 45533 | B33: =CCMFUT_F_0_Diário!F32 -> 66.1 | C33: =(B33-B32)/B32 -> 0.0088522589 | D33: =MAX($B$3:B33) -> 67.01 | E33: =(B33-D33)/D33 -> -0.013580063 | G33: 2025-S06 | H33: 77.05 | I33: =(H33-H32)/H32 -> 0.034505908 | J33: =MAX($H$3:H33) -> 77.05 | K33: =(H33-J33)/J33 -> 0 | S33: Média - 2σ | T33: =T29-2*T30 -> -0.10397492 | V33: COMPARATIVO DE DRAWDOWN
A34: =CCMFUT_F_0_Diário!B33 -> 45534 | B34: =CCMFUT_F_0_Diário!F33 -> 66.87 | C34: =(B34-B33)/B33 -> 0.011649017 | D34: =MAX($B$3:B34) -> 67.01 | E34: =(B34-D34)/D34 -> -0.0020892404 | G34: 2025-S07 | H34: 79.59 | I34: =(H34-H33)/H33 -> 0.032965607 | J34: =MAX($H$3:H34) -> 79.59 | K34: =(H34-J34)/J34 -> 0 | S34: Média + 2σ | T34: =T29+2*T30 -> 0.11052236 | V34: Métrica | W34: Diário | X34: Semanal | Y34: Mensal
A35: =CCMFUT_F_0_Diário!B34 -> 45537 | B35: =CCMFUT_F_0_Diário!F34 -> 66.92 | C35: =(B35-B34)/B34 -> 0.00074771946 | D35: =MAX($B$3:B35) -> 67.01 | E35: =(B35-D35)/D35 -> -0.0013430831 | G35: 2025-S08 | H35: 83.96 | I35: =(H35-H34)/H34 -> 0.054906395 | J35: =MAX($H$3:H35) -> 83.96 | K35: =(H35-J35)/J35 -> 0 | S35: Média - 3σ | T35: =T29-3*T30 -> -0.15759924 | V35: Drawdown Máximo | W35: =T11 -> -0.2742957 | X35: =T24 -> -0.22810261 | Y35: =T37 -> -0.20741694
A36: =CCMFUT_F_0_Diário!B35 -> 45538 | B36: =CCMFUT_F_0_Diário!F35 -> 67.36 | C36: =(B36-B35)/B35 -> 0.0065750149 | D36: =MAX($B$3:B36) -> 67.36 | E36: =(B36-D36)/D36 -> 0 | G36: 2025-S09 | H36: 85.48 | I36: =(H36-H35)/H35 -> 0.018103859 | J36: =MAX($H$3:H36) -> 85.48 | K36: =(H36-J36)/J36 -> 0 | S36: Média + 3σ | T36: =T29+3*T30 -> 0.16414668 | V36: Drawdown Médio | W36: =T12 -> -0.11457431 | X36: =T25 -> -0.079455482 | Y36: =T38 -> -0.074326653
A37: =CCMFUT_F_0_Diário!B36 -> 45539 | B37: =CCMFUT_F_0_Diário!F36 -> 68.44 | C37: =(B37-B36)/B36 -> 0.016033254 | D37: =MAX($B$3:B37) -> 68.44 | E37: =(B37-D37)/D37 -> 0 | G37: 2025-S10 | H37: 84.9 | I37: =(H37-H36)/H36 -> -0.0067852129 | J37: =MAX($H$3:H37) -> 85.48 | K37: =(H37-J37)/J37 -> -0.0067852129 | S37: Drawdown Máximo | T37: =MIN(Q3:Q27) -> -0.20741694
A38: =CCMFUT_F_0_Diário!B37 -> 45540 | B38: =CCMFUT_F_0_Diário!F37 -> 67.81 | C38: =(B38-B37)/B37 -> -0.0092051432 | D38: =MAX($B$3:B38) -> 68.44 | E38: =(B38-D38)/D38 -> -0.0092051432 | G38: 2025-S11 | H38: 86.54 | I38: =(H38-H37)/H37 -> 0.019316843 | J38: =MAX($H$3:H38) -> 86.54 | K38: =(H38-J38)/J38 -> 0 | S38: Drawdown Médio | T38: =AVERAGE(Q3:Q27) -> -0.074326653
A39: =CCMFUT_F_0_Diário!B38 -> 45541 | B39: =CCMFUT_F_0_Diário!F38 -> 68.27 | C39: =(B39-B38)/B38 -> 0.0067836602 | D39: =MAX($B$3:B39) -> 68.44 | E39: =(B39-D39)/D39 -> -0.0024839275 | G39: 2025-S12 | H39: 86.35 | I39: =(H39-H38)/H38 -> -0.0021955165 | J39: =MAX($H$3:H39) -> 86.54 | K39: =(H39-J39)/J39 -> -0.0021955165
A40: =CCMFUT_F_0_Diário!B39 -> 45544 | B40: =CCMFUT_F_0_Diário!F39 -> 69.71 | C40: =(B40-B39)/B39 -> 0.02109272 | D40: =MAX($B$3:B40) -> 69.71 | E40: =(B40-D40)/D40 -> 0 | G40: 2025-S13 | H40: 83.68 | I40: =(H40-H39)/H39 -> -0.030920672 | J40: =MAX($H$3:H40) -> 86.54 | K40: =(H40-J40)/J40 -> -0.033048301
...

Sheet Análise_À_Vista
A1: ANÁLISE DIÁRIA | G1: ANÁLISE SEMANAL | M1: ANÁLISE MENSAL | S1: RESUMO ESTATÍSTICO - DIÁRIO | V1: COMPARATIVO DE BANDAS DE DESVIO PADRÃO | AB1: CANAL DE REGRESSÃO LINEAR (1.5σ) | AI1: ESTATÍSTICAS DA REGRESSÃO | AL1: ANÁLISE DE REGRESSÃO POR ANO | BB1: ANÁLISE DO DESVIO DA VARIAÇÃO DIÁRIA POR ANO
A2: Data | B2: Fechamento | C2: Var % | D2: Máximo Acum | E2: Drawdown % | G2: Semana | H2: Fech. Semana | I2: Var % | J2: Máximo Acum | K2: Drawdown % | M2: Mês | N2: Fech. Mês | O2: Var % | P2: Máximo Acum | Q2: Drawdown % | S2: Métrica | T2: Valor | V2: Banda | W2: Diário | X2: Semanal | Y2: Mensal | AB2: Data | AC2: Fechamento | AD2: Índice | AE2: Regressão Linear | AF2: Banda Superior | AG2: Banda Inferior | AH2: Resíduo | AI2: Intercepto (a) | AJ2: =INTERCEPT(AC3:AC1136,AD3:AD1136) -> 82.304568 | AL2: Ano | AM2: Observações | AN2: Linha Início | AO2: Linha Fim | AP2: Intercepto (a) | AQ2: Slope (b) | AR2: Desvio Residual (σ) | AS2: R² | AT2: Preço Inicial | AU2: Preço Final | AV2: Var % | AW2: Banda 1.0σ | AX2: Banda 1.5σ | AY2: Banda 2.0σ | AZ2: Banda 2.5σ | BB2: Ano | BC2: Observações | BD2: Linha Início | BE2: Linha Fim | BF2: Média Var% | BG2: Desvio Padrão (σ) | BH2: Mínimo | BI2: Máximo | BJ2: Var% Anual | BK2: Preço Inicial | BL2: Preço Final | BM2: Banda 1σ | BN2: Banda 2σ
A3: =DATEVALUE(Sheet1!A2) -> 44564 | B3: =VALUE(Sheet1!B2) -> 92.01 | C3: =0 -> 0 | D3: =B3 -> 92.01 | E3: =0 -> 0 | G3: 2021-S52 | H3: =B3 -> 92.01 | I3: =0 -> 0 | J3: =H3 -> 92.01 | K3: =0 -> 0 | M3: jan/2022 | N3: =B24 -> 97.4 | O3: =0 -> 0 | P3: =N3 -> 97.4 | Q3: =0 -> 0 | S3: Média Variação | T3: =AVERAGE(C4:C1136) -> -0.00028524825 | V3: Média - 3σ | W3: =T9 -> -0.020277946 | X3: =T22 -> -0.063737163 | Y3: =T35 -> -0.19353318 | AB3: =A3 -> 44564 | AC3: =B3 -> 92.01 | AD3: =1 -> 1 | AE3: =INTERCEPT($AC$3:$AC$1136,$AD$3:$AD$1136)+SLOPE($AC$3:$AC$1136,$AD$3:$AD$1136)*AD3 -> 82.285856 | AF3: =AE3+$AJ$5*$AJ$4 -> 84.937516 | AG3: =AE3-$AJ$5*$AJ$4 -> 79.634197 | AH3: =AC3-AE3 -> 9.7241436 | AI3: Slope (b) | AJ3: =SLOPE(AC3:AC1136,AD3:AD1136) -> -0.018711963 | AL3: 2022 | AM3: 250 | AN3: 3 | AO3: 252 | AP3: {=INTERCEPT(AC3:AC252,ROW(AC3:AC252)-ROW(AC3)+1)} -> 95.781146 | AQ3: {=SLOPE(AC3:AC252,ROW(AC3:AC252)-ROW(AC3)+1)} -> -0.060764191 | AR3: {=STDEV(AC3:AC252-(AP3+AQ3*(ROW(AC3:AC252)-ROW(AC3)+1)))} -> 3.9911036 | AS3: {=RSQ(AC3:AC252,ROW(AC3:AC252)-ROW(AC3)+1)} -> 0.54794286 | AT3: =AC3 -> 92.01 | AU3: =AC252 -> 86.07 | AV3: =(AU3-AT3)/AT3 -> -0.0645582 | AW3: =AR3*1 -> 3.9911036 | AX3: =AR3*1.5 -> 5.9866554 | AY3: =AR3*2 -> 7.9822072 | AZ3: =AR3*2.5 -> 9.977759 | BB3: 2022 | BC3: =BE3-BD3+1 -> 250 | BD3: 3 | BE3: 252 | BF3: =AVERAGE(INDIRECT("C"&BD3&":C"&BE3)) -> -0.000246838 | BG3: =_xlfn.STDEV.S(INDIRECT("C"&BD3&":C"&BE3)) -> 0.006341864 | BH3: =MIN(INDIRECT("C"&BD3&":C"&BE3)) -> -0.035253744 | BI3: =MAX(INDIRECT("C"&BD3&":C"&BE3)) -> 0.021198975 | BJ3: {=(INDIRECT("B"&BE3)-INDIRECT("B"&BD3))/INDIRECT("B"&BD3)} -> -0.0645582 | BK3: {=INDIRECT("B"&BD3)} -> 92.01 | BL3: {=INDIRECT("B"&BE3)} -> 86.07 | BM3: =BG3 -> 0.006341864 | BN3: =BG3*2 -> 0.012683728
A4: =DATEVALUE(Sheet1!A3) -> 44565 | B4: =VALUE(Sheet1!B3) -> 92.72 | C4: =(B4-B3)/B3 -> 0.0077165525 | D4: =MAX(D3,B4) -> 92.72 | E4: =(B4-D4)/D4 -> 0 | G4: 2022-S01 | H4: =B8 -> 94.43 | I4: =(H4-H3)/H3 -> 0.026301489 | J4: =MAX(J3,H4) -> 94.43 | K4: =(H4-J4)/J4 -> 0 | M4: fev/2022 | N4: =B42 -> 97.34 | O4: =(N4-N3)/N3 -> -0.00061601643 | P4: =MAX(P3,N4) -> 97.4 | Q4: =(N4-P4)/P4 -> -0.00061601643 | S4: Desvio Padrão (σ) | T4: =_xlfn.STDEV.P(C4:C1136) -> 0.0066642327 | V4: Média - 2σ | W4: =T7 -> -0.013613714 | X4: =T20 -> -0.0429082 | Y4: =T33 -> -0.13083367 | AB4: =A4 -> 44565 | AC4: =B4 -> 92.72 | AD4: =2 -> 2 | AE4: =INTERCEPT($AC$3:$AC$1136,$AD$3:$AD$1136)+SLOPE($AC$3:$AC$1136,$AD$3:$AD$1136)*AD4 -> 82.267144 | AF4: =AE4+$AJ$5*$AJ$4 -> 84.918804 | AG4: =AE4-$AJ$5*$AJ$4 -> 79.615485 | AH4: =AC4-AE4 -> 10.452856 | AI4: Desvio Residual (σ) | AJ4: =STDEV(AH3:AH1136) -> 10.629804 | AL4: 2023 | AM4: 248 | AN4: 253 | AO4: 500 | AP4: {=INTERCEPT(AC253:AC500,ROW(AC253:AC500)-ROW(AC253)+1)} -> 81.576937 | AQ4: {=SLOPE(AC253:AC500,ROW(AC253:AC500)-ROW(AC253)+1)} -> -0.12505216 | AR4: {=STDEV(AC253:AC500-(AP4+AQ4*(ROW(AC253:AC500)-ROW(AC253)+1)))} -> 9.1820021 | AS4: {=RSQ(AC253:AC500,ROW(AC253:AC500)-ROW(AC253)+1)} -> 0.48836103 | AT4: =AC253 -> 86.09 | AU4: =AC500 -> 69.21 | AV4: =(AU4-AT4)/AT4 -> -0.19607388 | AW4: =AR4*1 -> 9.1820021 | AX4: =AR4*1.5 -> 13.773003 | AY4: =AR4*2 -> 18.364004 | AZ4: =AR4*2.5 -> 22.955005 | BB4: 2023 | BC4: =BE4-BD4+1 -> 248 | BD4: 253 | BE4: 500 | BF4: =AVERAGE(INDIRECT("C"&BD4&":C"&BE4)) -> -0.00084080394 | BG4: =_xlfn.STDEV.S(INDIRECT("C"&BD4&":C"&BE4)) -> 0.0087133371 | BH4: =MIN(INDIRECT("C"&BD4&":C"&BE4)) -> -0.031014621 | BI4: =MAX(INDIRECT("C"&BD4&":C"&BE4)) -> 0.027917867 | BJ4: {=(INDIRECT("B"&BE4)-INDIRECT("B"&BD4))/INDIRECT("B"&BD4)} -> -0.19607388 | BK4: {=INDIRECT("B"&BD4)} -> 86.09 | BL4: {=INDIRECT("B"&BE4)} -> 69.21 | BM4: =BG4 -> 0.0087133371 | BN4: =BG4*2 -> 0.017426674
A5: =DATEVALUE(Sheet1!A4) -> 44566 | B5: =VALUE(Sheet1!B4) -> 92.81 | C5: =(B5-B4)/B4 -> 0.00097066437 | D5: =MAX(D4,B5) -> 92.81 | E5: =(B5-D5)/D5 -> 0 | G5: 2022-S02 | H5: =B13 -> 97.16 | I5: =(H5-H4)/H4 -> 0.028910304 | J5: =MAX(J4,H5) -> 97.16 | K5: =(H5-J5)/J5 -> 0 | M5: mar/2022 | N5: =B65 -> 92.04 | O5: =(N5-N4)/N4 -> -0.054448325 | P5: =MAX(P4,N5) -> 97.4 | Q5: =(N5-P5)/P5 -> -0.055030801 | S5: Média - 1σ | T5: =T3-T4 -> -0.0069494809 | V5: Média - 1σ | W5: =T5 -> -0.0069494809 | X5: =T18 -> -0.022079236 | Y5: =T31 -> -0.068134158 | AB5: =A5 -> 44566 | AC5: =B5 -> 92.81 | AD5: =3 -> 3 | AE5: =INTERCEPT($AC$3:$AC$1136,$AD$3:$AD$1136)+SLOPE($AC$3:$AC$1136,$AD$3:$AD$1136)*AD5 -> 82.248432 | AF5: =AE5+$AJ$5*$AJ$4 -> 84.900092 | AG5: =AE5-$AJ$5*$AJ$4 -> 79.596773 | AH5: =AC5-AE5 -> 10.561568 | AI5: R² | AJ5: =RSQ(AC3:AC1136,AD3:AD1136) -> 0.24945518 | AL5: 2024 | AM5: 251 | AN5: 501 | AO5: 751 | AP5: {=INTERCEPT(AC501:AC751,ROW(AC501:AC751)-ROW(AC501)+1)} -> 58.654837 | AQ5: {=SLOPE(AC501:AC751,ROW(AC501:AC751)-ROW(AC501)+1)} -> 0.037451967 | AR5: {=STDEV(AC501:AC751-(AP5+AQ5*(ROW(AC501:AC751)-ROW(AC501)+1)))} -> 4.8011232 | AS5: {=RSQ(AC501:AC751,ROW(AC501:AC751)-ROW(AC501)+1)} -> 0.24285017 | AT5: =AC501 -> 69.75 | AU5: =AC751 -> 72.69 | AV5: =(AU5-AT5)/AT5 -> 0.042150538 | AW5: =AR5*1 -> 4.8011232 | AX5: =AR5*1.5 -> 7.2016848 | AY5: =AR5*2 -> 9.6022464 | AZ5: =AR5*2.5 -> 12.002808 | BB5: 2024 | BC5: =BE5-BD5+1 -> 251 | BD5: 501 | BE5: 751 | BF5: =AVERAGE(INDIRECT("C"&BD5&":C"&BE5)) -> 0.00021507211 | BG5: =_xlfn.STDEV.S(INDIRECT("C"&BD5&":C"&BE5)) -> 0.0062747803 | BH5: =MIN(INDIRECT("C"&BD5&":C"&BE5)) -> -0.018759019 | BI5: =MAX(INDIRECT("C"&BD5&":C"&BE5)) -> 0.022215852 | BJ5: {=(INDIRECT("B"&BE5)-INDIRECT("B"&BD5))/INDIRECT("B"&BD5)} -> 0.042150538 | BK5: {=INDIRECT("B"&BD5)} -> 69.75 | BL5: {=INDIRECT("B"&BE5)} -> 72.69 | BM5: =BG5 -> 0.0062747803 | BN5: =BG5*2 -> 0.012549561
A6: =DATEVALUE(Sheet1!A5) -> 44567 | B6: =VALUE(Sheet1!B5) -> 93.28 | C6: =(B6-B5)/B5 -> 0.0050641095 | D6: =MAX(D5,B6) -> 93.28 | E6: =(B6-D6)/D6 -> 0 | G6: 2022-S03 | H6: =B18 -> 97.93 | I6: =(H6-H5)/H5 -> 0.007925072 | J6: =MAX(J5,H6) -> 97.93 | K6: =(H6-J6)/J6 -> 0 | M6: abr/2022 | N6: =B83 -> 88.25 | O6: =(N6-N5)/N5 -> -0.041177749 | P6: =MAX(P5,N6) -> 97.4 | Q6: =(N6-P6)/P6 -> -0.093942505 | S6: Média + 1σ | T6: =T3+T4 -> 0.0063789844 | V6: Média | W6: =T3 -> -0.00028524825 | X6: =T16 -> -0.0012502725 | Y6: =T29 -> -0.0054346472 | AB6: =A6 -> 44567 | AC6: =B6 -> 93.28 | AD6: =4 -> 4 | AE6: =INTERCEPT($AC$3:$AC$1136,$AD$3:$AD$1136)+SLOPE($AC$3:$AC$1136,$AD$3:$AD$1136)*AD6 -> 82.22972 | AF6: =AE6+$AJ$5*$AJ$4 -> 84.88138 | AG6: =AE6-$AJ$5*$AJ$4 -> 79.578061 | AH6: =AC6-AE6 -> 11.05028 | AI6: Multiplicador Banda | AJ6: 1.5 | AL6: 2025 | AM6: 250 | AN6: 752 | AO6: 1001 | AP6: {=INTERCEPT(AC752:AC1001,ROW(AC752:AC1001)-ROW(AC752)+1)} -> 81.172169 | AQ6: {=SLOPE(AC752:AC1001,ROW(AC752:AC1001)-ROW(AC752)+1)} -> -0.075498715 | AR6: {=STDEV(AC752:AC1001-(AP6+AQ6*(ROW(AC752:AC1001)-ROW(AC752)+1)))} -> 6.0626934 | AS6: {=RSQ(AC752:AC1001,ROW(AC752:AC1001)-ROW(AC752)+1)} -> 0.44779584 | AT6: =AC752 -> 72.94 | AU6: =AC1001 -> 69.5 | AV6: =(AU6-AT6)/AT6 -> -0.047162051 | AW6: =AR6*1 -> 6.0626934 | AX6: =AR6*1.5 -> 9.0940401 | AY6: =AR6*2 -> 12.125387 | AZ6: =AR6*2.5 -> 15.156733 | BB6: 2025 | BC6: =BE6-BD6+1 -> 250 | BD6: 752 | BE6: 1001 | BF6: =AVERAGE(INDIRECT("C"&BD6&":C"&BE6)) -> -0.00016075566 | BG6: =_xlfn.STDEV.S(INDIRECT("C"&BD6&":C"&BE6)) -> 0.006137169 | BH6: =MIN(INDIRECT("C"&BD6&":C"&BE6)) -> -0.019994032 | BI6: =MAX(INDIRECT("C"&BD6&":C"&BE6)) -> 0.029780763 | BJ6: {=(INDIRECT("B"&BE6)-INDIRECT("B"&BD6))/INDIRECT("B"&BD6)} -> -0.047162051 | BK6: {=INDIRECT("B"&BD6)} -> 72.94 | BL6: {=INDIRECT("B"&BE6)} -> 69.5 | BM6: =BG6 -> 0.006137169 | BN6: =BG6*2 -> 0.012274338
A7: =DATEVALUE(Sheet1!A6) -> 44568 | B7: =VALUE(Sheet1!B6) -> 93.52 | C7: =(B7-B6)/B6 -> 0.0025728988 | D7: =MAX(D6,B7) -> 93.52 | E7: =(B7-D7)/D7 -> 0 | G7: 2022-S04 | H7: =B23 -> 97.42 | I7: =(H7-H6)/H6 -> -0.0052078015 | J7: =MAX(J6,H7) -> 97.93 | K7: =(H7-J7)/J7 -> -0.0052078015 | M7: mai/2022 | N7: =B106 -> 85.8 | O7: =(N7-N6)/N6 -> -0.02776204 | P7: =MAX(P6,N7) -> 97.4 | Q7: =(N7-P7)/P7 -> -0.11909651 | S7: Média - 2σ | T7: =T3-2*T4 -> -0.013613714 | V7: Média + 1σ | W7: =T6 -> 0.0063789844 | X7: =T19 -> 0.019578691 | Y7: =T32 -> 0.057264864 | AB7: =A7 -> 44568 | AC7: =B7 -> 93.52 | AD7: =5 -> 5 | AE7: =INTERCEPT($AC$3:$AC$1136,$AD$3:$AD$1136)+SLOPE($AC$3:$AC$1136,$AD$3:$AD$1136)*AD7 -> 82.211009 | AF7: =AE7+$AJ$5*$AJ$4 -> 84.862668 | AG7: =AE7-$AJ$5*$AJ$4 -> 79.559349 | AH7: =AC7-AE7 -> 11.308991 | AI7: Observações | AJ7: =1134 -> 1134 | AL7: 2026 | AM7: 135 | AN7: 1002 | AO7: 1136 | AP7: {=INTERCEPT(AC1002:AC1136,ROW(AC1002:AC1136)-ROW(AC1002)+1)} -> 70.057218 | AQ7: {=SLOPE(AC1002:AC1136,ROW(AC1002:AC1136)-ROW(AC1002)+1)} -> -0.044248854 | AR7: {=STDEV(AC1002:AC1136-(AP7+AQ7*(ROW(AC1002:AC1136)-ROW(AC1002)+1)))} -> 1.8490367 | AS7: {=RSQ(AC1002:AC1136,ROW(AC1002:AC1136)-ROW(AC1002)+1)} -> 0.46700845 | AT7: =AC1002 -> 69.45 | AU7: =AC1136 -> 64.94 | AV7: =(AU7-AT7)/AT7 -> -0.064938805 | AW7: =AR7*1 -> 1.8490367 | AX7: =AR7*1.5 -> 2.7735551 | AY7: =AR7*2 -> 3.6980734 | AZ7: =AR7*2.5 -> 4.6225918 | BB7: 2026 | BC7: =BE7-BD7+1 -> 135 | BD7: 1002 | BE7: 1136 | BF7: =AVERAGE(INDIRECT("C"&BD7&":C"&BE7)) -> -0.00049445611 | BG7: =_xlfn.STDEV.S(INDIRECT("C"&BD7&":C"&BE7)) -> 0.0040336279 | BH7: =MIN(INDIRECT("C"&BD7&":C"&BE7)) -> -0.019311634 | BI7: =MAX(INDIRECT("C"&BD7&":C"&BE7)) -> 0.0069454707 | BJ7: {=(INDIRECT("B"&BE7)-INDIRECT("B"&BD7))/INDIRECT("B"&BD7)} -> -0.064938805 | BK7: {=INDIRECT("B"&BD7)} -> 69.45 | BL7: {=INDIRECT("B"&BE7)} -> 64.94 | BM7: =BG7 -> 0.0040336279 | BN7: =BG7*2 -> 0.0080672557
A8: =DATEVALUE(Sheet1!A7) -> 44571 | B8: =VALUE(Sheet1!B7) -> 94.43 | C8: =(B8-B7)/B7 -> 0.0097305389 | D8: =MAX(D7,B8) -> 94.43 | E8: =(B8-D8)/D8 -> 0 | G8: 2022-S05 | H8: =B28 -> 96.97 | I8: =(H8-H7)/H7 -> -0.0046191747 | J8: =MAX(J7,H8) -> 97.93 | K8: =(H8-J8)/J8 -> -0.0098029205 | M8: jun/2022 | N8: =B127 -> 83.16 | O8: =(N8-N7)/N7 -> -0.030769231 | P8: =MAX(P7,N8) -> 97.4 | Q8: =(N8-P8)/P8 -> -0.14620123 | S8: Média + 2σ | T8: =T3+2*T4 -> 0.013043217 | V8: Média + 2σ | W8: =T8 -> 0.013043217 | X8: =T21 -> 0.040407655 | Y8: =T34 -> 0.11996437 | AB8: =A8 -> 44571 | AC8: =B8 -> 94.43 | AD8: =6 -> 6 | AE8: =INTERCEPT($AC$3:$AC$1136,$AD$3:$AD$1136)+SLOPE($AC$3:$AC$1136,$AD$3:$AD$1136)*AD8 -> 82.192297 | AF8: =AE8+$AJ$5*$AJ$4 -> 84.843956 | AG8: =AE8-$AJ$5*$AJ$4 -> 79.540637 | AH8: =AC8-AE8 -> 12.237703 | AL8: "TOTAL" | AM8: =SUM(AM3:AM7) -> 1134 | AN8: =MIN(AN3:AN7) -> 3 | AO8: =MAX(AO3:AO7) -> 1136 | AP8: =AJ2 -> 82.304568 | AQ8: =AJ3 -> -0.018711963 | AR8: =AJ4 -> 10.629804 | AS8: =AJ5 -> 0.24945518 | AT8: =AC3 -> 92.01 | AU8: =AC1136 -> 64.94 | AV8: =(AU8-AT8)/AT8 -> -0.29420715 | AW8: =AR8*1 -> 10.629804 | AX8: =AR8*1.5 -> 15.944706 | AY8: =AR8*2 -> 21.259608 | AZ8: =AR8*2.5 -> 26.57451 | BB8: TOTAL | BC8: =SUM(BC3:BC7) -> 1134 | BD8: 3 | BE8: 1136 | BF8: =AVERAGE(C3:C1136) -> -0.00028499671 | BG8: =_xlfn.STDEV.S(C3:C1136) -> 0.006664238 | BH8: =MIN(C3:C1136) -> -0.035253744 | BI8: =MAX(C3:C1136) -> 0.029780763 | BJ8: =(B1136-B3)/B3 -> -0.29420715 | BK8: =B3 -> 92.01 | BL8: =B1136 -> 64.94 | BM8: =BG8 -> 0.006664238 | BN8: =BG8*2 -> 0.013328476
A9: =DATEVALUE(Sheet1!A8) -> 44572 | B9: =VALUE(Sheet1!B8) -> 95.13 | C9: =(B9-B8)/B8 -> 0.0074128984 | D9: =MAX(D8,B9) -> 95.13 | E9: =(B9-D9)/D9 -> 0 | G9: 2022-S06 | H9: =B33 -> 95.98 | I9: =(H9-H8)/H8 -> -0.010209343 | J9: =MAX(J8,H9) -> 97.93 | K9: =(H9-J9)/J9 -> -0.019912182 | M9: jul/2022 | N9: =B148 -> 82.64 | O9: =(N9-N8)/N8 -> -0.0062530063 | P9: =MAX(P8,N9) -> 97.4 | Q9: =(N9-P9)/P9 -> -0.15154004 | S9: Média - 3σ | T9: =T3-3*T4 -> -0.020277946 | V9: Média + 3σ | W9: =T10 -> 0.01970745 | X9: =T23 -> 0.061236619 | Y9: =T36 -> 0.18266389 | AB9: =A9 -> 44572 | AC9: =B9 -> 95.13 | AD9: =7 -> 7 | AE9: =INTERCEPT($AC$3:$AC$1136,$AD$3:$AD$1136)+SLOPE($AC$3:$AC$1136,$AD$3:$AD$1136)*AD9 -> 82.173585 | AF9: =AE9+$AJ$5*$AJ$4 -> 84.825244 | AG9: =AE9-$AJ$5*$AJ$4 -> 79.521925 | AH9: =AC9-AE9 -> 12.956415
A10: =DATEVALUE(Sheet1!A9) -> 44573 | B10: =VALUE(Sheet1!B9) -> 95.27 | C10: =(B10-B9)/B9 -> 0.0014716703 | D10: =MAX(D9,B10) -> 95.27 | E10: =(B10-D10)/D10 -> 0 | G10: 2022-S07 | H10: =B38 -> 96.52 | I10: =(H10-H9)/H9 -> 0.0056261721 | J10: =MAX(J9,H10) -> 97.93 | K10: =(H10-J10)/J10 -> -0.014398039 | M10: ago/2022 | N10: =B171 -> 83.66 | O10: =(N10-N9)/N9 -> 0.012342691 | P10: =MAX(P9,N10) -> 97.4 | Q10: =(N10-P10)/P10 -> -0.14106776 | S10: Média + 3σ | T10: =T3+3*T4 -> 0.01970745 | AB10: =A10 -> 44573 | AC10: =B10 -> 95.27 | AD10: =8 -> 8 | AE10: =INTERCEPT($AC$3:$AC$1136,$AD$3:$AD$1136)+SLOPE($AC$3:$AC$1136,$AD$3:$AD$1136)*AD10 -> 82.154873 | AF10: =AE10+$AJ$5*$AJ$4 -> 84.806532 | AG10: =AE10-$AJ$5*$AJ$4 -> 79.503213 | AH10: =AC10-AE10 -> 13.115127 | AL10: RESUMO COMPARATIVO - DESVIO IDEAL | BB10: RESUMO ESTATÍSTICO - DESVIO DIÁRIO | BI10: ANÁLISE DE COBERTURA - DESVIO DIÁRIO
A11: =DATEVALUE(Sheet1!A10) -> 44574 | B11: =VALUE(Sheet1!B10) -> 96.5 | C11: =(B11-B10)/B10 -> 0.012910675 | D11: =MAX(D10,B11) -> 96.5 | E11: =(B11-D11)/D11 -> 0 | G11: 2022-S08 | H11: =B42 -> 97.34 | I11: =(H11-H10)/H10 -> 0.0084956486 | J11: =MAX(J10,H11) -> 97.93 | K11: =(H11-J11)/J11 -> -0.0060247115 | M11: set/2022 | N11: =B191 -> 84.42 | O11: =(N11-N10)/N10 -> 0.0090843892 | P11: =MAX(P10,N11) -> 97.4 | Q11: =(N11-P11)/P11 -> -0.13326489 | S11: Drawdown Máximo | T11: =MIN(E3:E1136) -> -0.49326275 | V11: COMPARATIVO DE DRAWDOWN | AB11: =A11 -> 44574 | AC11: =B11 -> 96.5 | AD11: =9 -> 9 | AE11: =INTERCEPT($AC$3:$AC$1136,$AD$3:$AD$1136)+SLOPE($AC$3:$AC$1136,$AD$3:$AD$1136)*AD11 -> 82.136161 | AF11: =AE11+$AJ$5*$AJ$4 -> 84.78782 | AG11: =AE11-$AJ$5*$AJ$4 -> 79.484501 | AH11: =AC11-AE11 -> 14.363839 | AL11: Métrica | AM11: Mínimo | AN11: Máximo | AO11: Média | AP11: Mediana | AQ11: Desvio Padrão | AR11: CV (%) | AS11: Total | BB11: Métrica | BC11: Desvio σ Diário | BD11: Média Var% | BE11: Mínimo | BF11: Máximo | BG11: Var% Anual | BI11: Multiplicador | BJ11: Banda (σ médio) | BK11: Cobertura Real | BL11: Teórico Normal | BM11: Gap | BN11: Status
A12: =DATEVALUE(Sheet1!A11) -> 44575 | B12: =VALUE(Sheet1!B11) -> 96.77 | C12: =(B12-B11)/B11 -> 0.0027979275 | D12: =MAX(D11,B12) -> 96.77 | E12: =(B12-D12)/D12 -> 0 | G12: 2022-S09 | H12: =B46 -> 100.19 | I12: =(H12-H11)/H11 -> 0.029278817 | J12: =MAX(J11,H12) -> 100.19 | K12: =(H12-J12)/J12 -> 0 | M12: out/2022 | N12: =B212 -> 85.11 | O12: =(N12-N11)/N11 -> 0.0081734186 | P12: =MAX(P11,N12) -> 97.4 | Q12: =(N12-P12)/P12 -> -0.1261807 | S12: Drawdown Médio | T12: =AVERAGEIF(E3:E1136,"<0") -> -0.31308799 | V12: Métrica | W12: Diário | X12: Semanal | Y12: Mensal | AB12: =A12 -> 44575 | AC12: =B12 -> 96.77 | AD12: =10 -> 10 | AE12: =INTERCEPT($AC$3:$AC$1136,$AD$3:$AD$1136)+SLOPE($AC$3:$AC$1136,$AD$3:$AD$1136)*AD12 -> 82.117449 | AF12: =AE12+$AJ$5*$AJ$4 -> 84.769108 | AG12: =AE12-$AJ$5*$AJ$4 -> 79.465789 | AH12: =AC12-AE12 -> 14.652551 | AL12: Desvio Residual (σ) | AM12: =MIN(AR3:AR7) -> 1.8490367 | AN12: =MAX(AR3:AR7) -> 9.1820021 | AO12: =AVERAGE(AR3:AR7) -> 5.1771918 | AP12: =MEDIAN(AR3:AR7) -> 4.8011232 | AQ12: =STDEV(AR3:AR7) -> 2.7132761 | AR12: =AN12/AP12 -> 1.9124696 | AS12: =AR8 -> 10.629804 | BB12: Mínimo | BC12: =MIN(BG3:BG7) -> 0.0040336279 | BD12: =MIN(BF3:BF7) -> -0.00084080394 | BE12: =MIN(BH3:BH7) -> -0.035253744 | BF12: =MIN(BI3:BI7) -> 0.0069454707 | BG12: =MIN(BJ3:BJ7) -> -0.19607388 | BI12: 1 | BJ12: =$BC$14*BI12 -> 0.0063001557 | BK12: =COUNTIFS(C3:C1136,">="&-BJ12,C3:C1136,"<="&BJ12)/COUNT(C3:C1136) -> 0.74955908 | BL12: 0.6827 | BM12: =BK12-BL12 -> 0.066859083 | BN12: =IF(ABS(BM12)<0.1,"✅ OK",IF(ABS(BM12)<0.2,"⚠️ Moderado","❌ Alto gap")) -> ✅ OK
A13: =DATEVALUE(Sheet1!A12) -> 44578 | B13: =VALUE(Sheet1!B12) -> 97.16 | C13: =(B13-B12)/B12 -> 0.0040301746 | D13: =MAX(D12,B13) -> 97.16 | E13: =(B13-D13)/D13 -> 0 | G13: 2022-S10 | H13: =B51 -> 103.9 | I13: =(H13-H12)/H12 -> 0.037029644 | J13: =MAX(J12,H13) -> 103.9 | K13: =(H13-J13)/J13 -> 0 | M13: nov/2022 | N13: =B232 -> 86 | O13: =(N13-N12)/N12 -> 0.010457056 | P13: =MAX(P12,N13) -> 97.4 | Q13: =(N13-P13)/P13 -> -0.11704312 | V13: Drawdown Máximo | W13: =T11 -> -0.49326275 | X13: =T24 -> -0.48864293 | Y13: =T37 -> -0.44815195 | AB13: =A13 -> 44578 | AC13: =B13 -> 97.16 | AD13: =11 -> 11 | AE13: =INTERCEPT($AC$3:$AC$1136,$AD$3:$AD$1136)+SLOPE($AC$3:$AC$1136,$AD$3:$AD$1136)*AD13 -> 82.098737 | AF13: =AE13+$AJ$5*$AJ$4 -> 84.750396 | AG13: =AE13-$AJ$5*$AJ$4 -> 79.447077 | AH13: =AC13-AE13 -> 15.061263 | AL13: R² | AM13: =MIN(AS3:AS7) -> 0.24285017 | AN13: =MAX(AS3:AS7) -> 0.54794286 | AO13: =AVERAGE(AS3:AS7) -> 0.43879167 | AP13: =MEDIAN(AS3:AS7) -> 0.46700845 | AQ13: =STDEV(AS3:AS7) -> 0.1158031 | AR13: =AN13/AP13 -> 1.173304 | AS13: =AS8 -> 0.24945518 | BB13: Máximo | BC13: =MAX(BG3:BG7) -> 0.0087133371 | BD13: =MAX(BF3:BF7) -> 0.00021507211 | BE13: =MAX(BH3:BH7) -> -0.018759019 | BF13: =MAX(BI3:BI7) -> 0.029780763 | BG13: =MAX(BJ3:BJ7) -> 0.042150538 | BI13: 1.5 | BJ13: =$BC$14*BI13 -> 0.0094502335 | BK13: =COUNTIFS(C3:C1136,">="&-BJ13,C3:C1136,"<="&BJ13)/COUNT(C3:C1136) -> 0.8712522 | BL13: 0.8664 | BM13: =BK13-BL13 -> 0.0048522046 | BN13: =IF(ABS(BM13)<0.1,"✅ OK",IF(ABS(BM13)<0.2,"⚠️ Moderado","❌ Alto gap")) -> ✅ OK
A14: =DATEVALUE(Sheet1!A13) -> 44579 | B14: =VALUE(Sheet1!B13) -> 97.39 | C14: =(B14-B13)/B13 -> 0.0023672293 | D14: =MAX(D13,B14) -> 97.39 | E14: =(B14-D14)/D14 -> 0 | G14: 2022-S11 | H14: =B56 -> 102.63 | I14: =(H14-H13)/H13 -> -0.012223292 | J14: =MAX(J13,H14) -> 103.9 | K14: =(H14-J14)/J14 -> -0.012223292 | M14: dez/2022 | N14: =B252 -> 86.07 | O14: =(N14-N13)/N13 -> 0.00081395349 | P14: =MAX(P13,N14) -> 97.4 | Q14: =(N14-P14)/P14 -> -0.11632444 | S14: RESUMO ESTATÍSTICO - SEMANAL | V14: Drawdown Médio | W14: =T12 -> -0.31308799 | X14: =T25 -> -0.31415363 | Y14: =T38 -> -0.27134763 | AB14: =A14 -> 44579 | AC14: =B14 -> 97.39 | AD14: =12 -> 12 | AE14: =INTERCEPT($AC$3:$AC$1136,$AD$3:$AD$1136)+SLOPE($AC$3:$AC$1136,$AD$3:$AD$1136)*AD14 -> 82.080025 | AF14: =AE14+$AJ$5*$AJ$4 -> 84.731684 | AG14: =AE14-$AJ$5*$AJ$4 -> 79.428365 | AH14: =AC14-AE14 -> 15.309975 | AL14: Slope (b) | AM14: =MIN(AQ3:AQ7) -> -0.12505216 | AN14: =MAX(AQ3:AQ7) -> 0.037451967 | AO14: =AVERAGE(AQ3:AQ7) -> -0.05362239 | AP14: =MEDIAN(AQ3:AQ7) -> -0.060764191 | AQ14: =STDEV(AQ3:AQ7) -> 0.059190777 | AR14: =AN14/AP14 -> -0.61634931 | AS14: =AQ8 -> -0.018711963 | BB14: Média | BC14: =AVERAGE(BG3:BG7) -> 0.0063001557 | BD14: =AVERAGE(BF3:BF7) -> -0.00030555632 | BE14: =AVERAGE(BH3:BH7) -> -0.02486661 | BF14: =AVERAGE(BI3:BI7) -> 0.021611786 | BG14: =AVERAGE(BJ3:BJ7) -> -0.066116479 | BI14: 2 | BJ14: =$BC$14*BI14 -> 0.012600311 | BK14: =COUNTIFS(C3:C1136,">="&-BJ14,C3:C1136,"<="&BJ14)/COUNT(C3:C1136) -> 0.9303351 | BL14: 0.9545 | BM14: =BK14-BL14 -> -0.024164903 | BN14: =IF(ABS(BM14)<0.1,"✅ OK",IF(ABS(BM14)<0.2,"⚠️ Moderado","❌ Alto gap")) -> ✅ OK
A15: =DATEVALUE(Sheet1!A14) -> 44580 | B15: =VALUE(Sheet1!B14) -> 97.7 | C15: =(B15-B14)/B14 -> 0.0031830783 | D15: =MAX(D14,B15) -> 97.7 | E15: =(B15-D15)/D15 -> 0 | G15: 2022-S12 | H15: =B61 -> 96.16 | I15: =(H15-H14)/H14 -> -0.063041996 | J15: =MAX(J14,H15) -> 103.9 | K15: =(H15-J15)/J15 -> -0.074494706 | M15: jan/2023 | N15: =B275 -> 85.76 | O15: =(N15-N14)/N14 -> -0.0036017195 | P15: =MAX(P14,N15) -> 97.4 | Q15: =(N15-P15)/P15 -> -0.11950719 | S15: Métrica | T15: Valor | AB15: =A15 -> 44580 | AC15: =B15 -> 97.7 | AD15: =13 -> 13 | AE15: =INTERCEPT($AC$3:$AC$1136,$AD$3:$AD$1136)+SLOPE($AC$3:$AC$1136,$AD$3:$AD$1136)*AD15 -> 82.061313 | AF15: =AE15+$AJ$5*$AJ$4 -> 84.712972 | AG15: =AE15-$AJ$5*$AJ$4 -> 79.409653 | AH15: =AC15-AE15 -> 15.638687 | AL15: Banda 1.0σ | AM15: =MIN(AW3:AW7) -> 1.8490367 | AN15: =MAX(AW3:AW7) -> 9.1820021 | AO15: =AVERAGE(AW3:AW7) -> 5.1771918 | AP15: =MEDIAN(AW3:AW7) -> 4.8011232 | AQ15: =STDEV(AW3:AW7) -> 2.7132761 | AR15: =AN15/AP15 -> 1.9124696 | AS15: =AW8 -> 10.629804 | BB15: Mediana | BC15: =MEDIAN(BG3:BG7) -> 0.0062747803 | BD15: =MEDIAN(BF3:BF7) -> -0.000246838 | BE15: =MEDIAN(BH3:BH7) -> -0.019994032 | BF15: =MEDIAN(BI3:BI7) -> 0.022215852 | BG15: =MEDIAN(BJ3:BJ7) -> -0.0645582 | BI15: 2.5 | BJ15: =$BC$14*BI15 -> 0.015750389 | BK15: =COUNTIFS(C3:C1136,">="&-BJ15,C3:C1136,"<="&BJ15)/COUNT(C3:C1136) -> 0.9638448 | BL15: 0.9876 | BM15: =BK15-BL15 -> -0.023755203 | BN15: =IF(ABS(BM15)<0.1,"✅ OK",IF(ABS(BM15)<0.2,"⚠️ Moderado","❌ Alto gap")) -> ✅ OK
A16: =DATEVALUE(Sheet1!A15) -> 44581 | B16: =VALUE(Sheet1!B15) -> 98.13 | C16: =(B16-B15)/B15 -> 0.0044012282 | D16: =MAX(D15,B16) -> 98.13 | E16: =(B16-D16)/D16 -> 0 | G16: 2022-S13 | H16: =B66 -> 91.55 | I16: =(H16-H15)/H15 -> -0.047940932 | J16: =MAX(J15,H16) -> 103.9 | K16: =(H16-J16)/J16 -> -0.11886429 | M16: fev/2023 | N16: =B293 -> 86.11 | O16: =(N16-N15)/N15 -> 0.0040811567 | P16: =MAX(P15,N16) -> 97.4 | Q16: =(N16-P16)/P16 -> -0.11591376 | S16: Média Variação | T16: =AVERAGE(I4:I240) -> -0.0012502725 | AB16: =A16 -> 44581 | AC16: =B16 -> 98.13 | AD16: =14 -> 14 | AE16: =INTERCEPT($AC$3:$AC$1136,$AD$3:$AD$1136)+SLOPE($AC$3:$AC$1136,$AD$3:$AD$1136)*AD16 -> 82.042601 | AF16: =AE16+$AJ$5*$AJ$4 -> 84.69426 | AG16: =AE16-$AJ$5*$AJ$4 -> 79.390941 | AH16: =AC16-AE16 -> 16.087399 | AL16: Banda 1.5σ | AM16: =MIN(AX3:AX7) -> 2.7735551 | AN16: =MAX(AX3:AX7) -> 13.773003 | AO16: =AVERAGE(AX3:AX7) -> 7.7657877 | AP16: =MEDIAN(AX3:AX7) -> 7.2016848 | AQ16: =STDEV(AX3:AX7) -> 4.0699141 | AR16: =AN16/AP16 -> 1.9124696 | AS16: =AX8 -> 15.944706 | BB16: Desvio Padrão | BC16: =_xlfn.STDEV.S(BG3:BG7) -> 0.0016575238 | BD16: =_xlfn.STDEV.S(BF3:BF7) -> 0.00039295107 | BI16: 3 | BJ16: =$BC$14*BI16 -> 0.018900467 | BK16: =COUNTIFS(C3:C1136,">="&-BJ16,C3:C1136,"<="&BJ16)/COUNT(C3:C1136) -> 0.97795414 | BL16: 0.9973 | BM16: =BK16-BL16 -> -0.019345855 | BN16: =IF(ABS(BM16)<0.1,"✅ OK",IF(ABS(BM16)<0.2,"⚠️ Moderado","❌ Alto gap")) -> ✅ OK
A17: =DATEVALUE(Sheet1!A16) -> 44582 | B17: =VALUE(Sheet1!B16) -> 98.33 | C17: =(B17-B16)/B16 -> 0.0020381127 | D17: =MAX(D16,B17) -> 98.33 | E17: =(B17-D17)/D17 -> 0 | G17: 2022-S14 | H17: =B71 -> 88.9 | I17: =(H17-H16)/H16 -> -0.028945931 | J17: =MAX(J16,H17) -> 103.9 | K17: =(H17-J17)/J17 -> -0.14436959 | M17: mar/2023 | N17: =B315 -> 82.6 | O17: =(N17-N16)/N16 -> -0.040761816 | P17: =MAX(P16,N17) -> 97.4 | Q17: =(N17-P17)/P17 -> -0.15195072 | S17: Desvio Padrão (σ) | T17: =_xlfn.STDEV.P(I4:I240) -> 0.020828964 | AB17: =A17 -> 44582 | AC17: =B17 -> 98.33 | AD17: =15 -> 15 | AE17: =INTERCEPT($AC$3:$AC$1136,$AD$3:$AD$1136)+SLOPE($AC$3:$AC$1136,$AD$3:$AD$1136)*AD17 -> 82.023889 | AF17: =AE17+$AJ$5*$AJ$4 -> 84.675548 | AG17: =AE17-$AJ$5*$AJ$4 -> 79.372229 | AH17: =AC17-AE17 -> 16.306111 | AL17: Banda 2.0σ | AM17: =MIN(AY3:AY7) -> 3.6980734 | AN17: =MAX(AY3:AY7) -> 18.364004 | AO17: =AVERAGE(AY3:AY7) -> 10.354384 | AP17: =MEDIAN(AY3:AY7) -> 9.6022464 | AQ17: =STDEV(AY3:AY7) -> 5.4265521 | AR17: =AN17/AP17 -> 1.9124696 | AS17: =AY8 -> 21.259608 | BB17: CV (%) | BC17: =BC16/BC14 -> 0.26309252 | BD17: =BD16/ABS(BD14) -> 1.2860185
A18: =DATEVALUE(Sheet1!A17) -> 44585 | B18: =VALUE(Sheet1!B17) -> 97.93 | C18: =(B18-B17)/B17 -> -0.0040679345 | D18: =MAX(D17,B18) -> 98.33 | E18: =(B18-D18)/D18 -> -0.0040679345 | G18: 2022-S15 | H18: =B75 -> 87.63 | I18: =(H18-H17)/H17 -> -0.014285714 | J18: =MAX(J17,H18) -> 103.9 | K18: =(H18-J18)/J18 -> -0.15659288 | M18: abr/2023 | N18: =B333 -> 65.61 | O18: =(N18-N17)/N17 -> -0.20569007 | P18: =MAX(P17,N18) -> 97.4 | Q18: =(N18-P18)/P18 -> -0.32638604 | S18: Média - 1σ | T18: =T16-T17 -> -0.022079236 | AB18: =A18 -> 44585 | AC18: =B18 -> 97.93 | AD18: =16 -> 16 | AE18: =INTERCEPT($AC$3:$AC$1136,$AD$3:$AD$1136)+SLOPE($AC$3:$AC$1136,$AD$3:$AD$1136)*AD18 -> 82.005177 | AF18: =AE18+$AJ$5*$AJ$4 -> 84.656837 | AG18: =AE18-$AJ$5*$AJ$4 -> 79.353517 | AH18: =AC18-AE18 -> 15.924823 | AL18: Banda 2.5σ | AM18: =MIN(AZ3:AZ7) -> 4.6225918 | AN18: =MAX(AZ3:AZ7) -> 22.955005 | AO18: =AVERAGE(AZ3:AZ7) -> 12.94298 | AP18: =MEDIAN(AZ3:AZ7) -> 12.002808 | AQ18: =STDEV(AZ3:AZ7) -> 6.7831901 | AR18: =AN18/AP18 -> 1.9124696 | AS18: =AZ8 -> 26.57451 | BB18: TOTAL | BC18: =BG8 -> 0.006664238 | BD18: =BF8 -> -0.00028499671 | BE18: =BH8 -> -0.035253744 | BF18: =BI8 -> 0.029780763 | BG18: =BJ8 -> -0.29420715
A19: =DATEVALUE(Sheet1!A18) -> 44586 | B19: =VALUE(Sheet1!B18) -> 97.76 | C19: =(B19-B18)/B18 -> -0.0017359338 | D19: =MAX(D18,B19) -> 98.33 | E19: =(B19-D19)/D19 -> -0.0057968067 | G19: 2022-S16 | H19: =B79 -> 88.71 | I19: =(H19-H18)/H18 -> 0.012324546 | J19: =MAX(J18,H19) -> 103.9 | K19: =(H19-J19)/J19 -> -0.14619827 | M19: mai/2023 | N19: =B356 -> 53.9 | O19: =(N19-N18)/N18 -> -0.17847889 | P19: =MAX(P18,N19) -> 97.4 | Q19: =(N19-P19)/P19 -> -0.44661191 | S19: Média + 1σ | T19: =T16+T17 -> 0.019578691 | AB19: =A19 -> 44586 | AC19: =B19 -> 97.76 | AD19: =17 -> 17 | AE19: =INTERCEPT($AC$3:$AC$1136,$AD$3:$AD$1136)+SLOPE($AC$3:$AC$1136,$AD$3:$AD$1136)*AD19 -> 81.986465 | AF19: =AE19+$AJ$5*$AJ$4 -> 84.638125 | AG19: =AE19-$AJ$5*$AJ$4 -> 79.334805 | AH19: =AC19-AE19 -> 15.773535
A20: =DATEVALUE(Sheet1!A19) -> 44587 | B20: =VALUE(Sheet1!B19) -> 97.9 | C20: =(B20-B19)/B19 -> 0.0014320786 | D20: =MAX(D19,B20) -> 98.33 | E20: =(B20-D20)/D20 -> -0.0043730296 | G20: 2022-S17 | H20: =B84 -> 87.87 | I20: =(H20-H19)/H19 -> -0.0094690565 | J20: =MAX(J19,H20) -> 103.9 | K20: =(H20-J20)/J20 -> -0.15428296 | M20: jun/2023 | N20: =B376 -> 55.36 | O20: =(N20-N19)/N19 -> 0.027087199 | P20: =MAX(P19,N20) -> 97.4 | Q20: =(N20-P20)/P20 -> -0.43162218 | S20: Média - 2σ | T20: =T16-2*T17 -> -0.0429082 | AB20: =A20 -> 44587 | AC20: =B20 -> 97.9 | AD20: =18 -> 18 | AE20: =INTERCEPT($AC$3:$AC$1136,$AD$3:$AD$1136)+SLOPE($AC$3:$AC$1136,$AD$3:$AD$1136)*AD20 -> 81.967753 | AF20: =AE20+$AJ$5*$AJ$4 -> 84.619413 | AG20: =AE20-$AJ$5*$AJ$4 -> 79.316093 | AH20: =AC20-AE20 -> 15.932247 | AL20: ANÁLISE E RECOMENDAÇÃO DE DESVIO PADRÃO IDEAL | BB20: CONCLUSÃO E RECOMENDAÇÃO - DESVIO DIÁRIO IDEAL
A21: =DATEVALUE(Sheet1!A20) -> 44588 | B21: =VALUE(Sheet1!B20) -> 97.37 | C21: =(B21-B20)/B20 -> -0.0054136874 | D21: =MAX(D20,B21) -> 98.33 | E21: =(B21-D21)/D21 -> -0.0097630428 | G21: 2022-S18 | H21: =B89 -> 86.15 | I21: =(H21-H20)/H20 -> -0.019574371 | J21: =MAX(J20,H21) -> 103.9 | K21: =(H21-J21)/J21 -> -0.17083734 | M21: jul/2023 | N21: =B398 -> 53.75 | O21: =(N21-N20)/N20 -> -0.02908237 | P21: =MAX(P20,N21) -> 97.4 | Q21: =(N21-P21)/P21 -> -0.44815195 | S21: Média + 2σ | T21: =T16+2*T17 -> 0.040407655 | AB21: =A21 -> 44588 | AC21: =B21 -> 97.37 | AD21: =19 -> 19 | AE21: =INTERCEPT($AC$3:$AC$1136,$AD$3:$AD$1136)+SLOPE($AC$3:$AC$1136,$AD$3:$AD$1136)*AD21 -> 81.949041 | AF21: =AE21+$AJ$5*$AJ$4 -> 84.600701 | AG21: =AE21-$AJ$5*$AJ$4 -> 79.297381 | AH21: =AC21-AE21 -> 15.420959 | AL21: Desvio Médio Anual | AN21: =AP12 -> 4.8011232 | AQ21: Média do desvio residual de cada ano | BB21: Observação 1: | BD21: A distribuição das variações diárias é muito mais próxima da normal do que os resíduos da regressão
A22: =DATEVALUE(Sheet1!A21) -> 44589 | B22: =VALUE(Sheet1!B21) -> 97.4 | C22: =(B22-B21)/B21 -> 0.00030810311 | D22: =MAX(D21,B22) -> 98.33 | E22: =(B22-D22)/D22 -> -0.0094579477 | G22: 2022-S19 | H22: =B94 -> 87.97 | I22: =(H22-H21)/H21 -> 0.021125943 | J22: =MAX(J21,H22) -> 103.9 | K22: =(H22-J22)/J22 -> -0.1533205 | M22: ago/2023 | N22: =B421 -> 53.88 | O22: =(N22-N21)/N21 -> 0.0024186047 | P22: =MAX(P21,N22) -> 97.4 | Q22: =(N22-P22)/P22 -> -0.44681725 | S22: Média - 3σ | T22: =T16-3*T17 -> -0.063737163 | AB22: =A22 -> 44589 | AC22: =B22 -> 97.4 | AD22: =20 -> 20 | AE22: =INTERCEPT($AC$3:$AC$1136,$AD$3:$AD$1136)+SLOPE($AC$3:$AC$1136,$AD$3:$AD$1136)*AD22 -> 81.930329 | AF22: =AE22+$AJ$5*$AJ$4 -> 84.581989 | AG22: =AE22-$AJ$5*$AJ$4 -> 79.278669 | AH22: =AC22-AE22 -> 15.469671 | AL22: Desvio Total (Amostra Completa) | AN22: =AS12 -> 10.629804 | AQ22: Desvio residual considerando todos os dados | BB22: Observação 2: | BD22: O desvio padrão diário é CONSISTENTE entre os anos (CV = baixo), indicando volatilidade estável
A23: =DATEVALUE(Sheet1!A22) -> 44592 | B23: =VALUE(Sheet1!B22) -> 97.42 | C23: =(B23-B22)/B22 -> 0.00020533881 | D23: =MAX(D22,B23) -> 98.33 | E23: =(B23-D23)/D23 -> -0.009254551 | G23: 2022-S20 | H23: =B99 -> 88.03 | I23: =(H23-H22)/H22 -> 0.0006820507 | J23: =MAX(J22,H23) -> 103.9 | K23: =(H23-J23)/J23 -> -0.15274302 | M23: set/2023 | N23: =B440 -> 57.47 | O23: =(N23-N22)/N22 -> 0.066629547 | P23: =MAX(P22,N23) -> 97.4 | Q23: =(N23-P23)/P23 -> -0.40995893 | S23: Média + 3σ | T23: =T16+3*T17 -> 0.061236619 | AB23: =A23 -> 44592 | AC23: =B23 -> 97.42 | AD23: =21 -> 21 | AE23: =INTERCEPT($AC$3:$AC$1136,$AD$3:$AD$1136)+SLOPE($AC$3:$AC$1136,$AD$3:$AD$1136)*AD23 -> 81.911617 | AF23: =AE23+$AJ$5*$AJ$4 -> 84.563277 | AG23: =AE23-$AJ$5*$AJ$4 -> 79.259958 | AH23: =AC23-AE23 -> 15.508383 | AL23: Razão Total/Média | AN23: =AN22/AN21 -> 2.2140244 | AQ23: Quanto o total é maior que a média anual | BB23: Observação 3: | BD23: O desvio TOTAL (0.67%) é muito próximo da média dos anos (0.63%), diferente da análise de regressão
A24: =DATEVALUE(Sheet1!A23) -> 44593 | B24: =VALUE(Sheet1!B23) -> 97.4 | C24: =(B24-B23)/B23 -> -0.00020529665 | D24: =MAX(D23,B24) -> 98.33 | E24: =(B24-D24)/D24 -> -0.0094579477 | G24: 2022-S21 | H24: =B104 -> 86.84 | I24: =(H24-H23)/H23 -> -0.013518119 | J24: =MAX(J23,H24) -> 103.9 | K24: =(H24-J24)/J24 -> -0.16419634 | M24: out/2023 | N24: =B462 -> 60.03 | O24: =(N24-N23)/N23 -> 0.04454498 | P24: =MAX(P23,N24) -> 97.4 | Q24: =(N24-P24)/P24 -> -0.38367556 | S24: Drawdown Máximo | T24: =MIN(K3:K240) -> -0.48864293 | AB24: =A24 -> 44593 | AC24: =B24 -> 97.4 | AD24: =22 -> 22 | AE24: =INTERCEPT($AC$3:$AC$1136,$AD$3:$AD$1136)+SLOPE($AC$3:$AC$1136,$AD$3:$AD$1136)*AD24 -> 81.892905 | AF24: =AE24+$AJ$5*$AJ$4 -> 84.544565 | AG24: =AE24-$AJ$5*$AJ$4 -> 79.241246 | AH24: =AC24-AE24 -> 15.507095 | BB24: Observação 4: | BD24: Todos os multiplicadores testados têm gaps pequenos vs teórico normal (< 10%)
A25: =DATEVALUE(Sheet1!A24) -> 44594 | B25: =VALUE(Sheet1!B24) -> 97.14 | C25: =(B25-B24)/B24 -> -0.0026694045 | D25: =MAX(D24,B25) -> 98.33 | E25: =(B25-D25)/D25 -> -0.012102105 | G25: 2022-S22 | H25: =B109 -> 84.8 | I25: =(H25-H24)/H24 -> -0.023491479 | J25: =MAX(J24,H25) -> 103.9 | K25: =(H25-J25)/J25 -> -0.18383061 | M25: nov/2023 | N25: =B482 -> 62.63 | O25: =(N25-N24)/N24 -> 0.043311677 | P25: =MAX(P24,N25) -> 97.4 | Q25: =(N25-P25)/P25 -> -0.35698152 | S25: Drawdown Médio | T25: =AVERAGEIF(K3:K240,"<0") -> -0.31415363 | AB25: =A25 -> 44594 | AC25: =B25 -> 97.14 | AD25: =23 -> 23 | AE25: =INTERCEPT($AC$3:$AC$1136,$AD$3:$AD$1136)+SLOPE($AC$3:$AC$1136,$AD$3:$AD$1136)*AD25 -> 81.874193 | AF25: =AE25+$AJ$5*$AJ$4 -> 84.525853 | AG25: =AE25-$AJ$5*$AJ$4 -> 79.222534 | AH25: =AC25-AE25 -> 15.265807 | AL25: Desvio Mínimo Anual | AN25: =AM12 -> 1.8490367 | AQ25: Ano com menor volatilidade
A26: =DATEVALUE(Sheet1!A25) -> 44595 | B26: =VALUE(Sheet1!B25) -> 96.82 | C26: =(B26-B25)/B25 -> -0.0032942145 | D26: =MAX(D25,B26) -> 98.33 | E26: =(B26-D26)/D26 -> -0.015356453 | G26: 2022-S23 | H26: =B114 -> 85.41 | I26: =(H26-H25)/H25 -> 0.0071933962 | J26: =MAX(J25,H26) -> 103.9 | K26: =(H26-J26)/J26 -> -0.17795958 | M26: dez/2023 | N26: =B500 -> 69.21 | O26: =(N26-N25)/N25 -> 0.10506147 | P26: =MAX(P25,N26) -> 97.4 | Q26: =(N26-P26)/P26 -> -0.28942505 | AB26: =A26 -> 44595 | AC26: =B26 -> 96.82 | AD26: =24 -> 24 | AE26: =INTERCEPT($AC$3:$AC$1136,$AD$3:$AD$1136)+SLOPE($AC$3:$AC$1136,$AD$3:$AD$1136)*AD26 -> 81.855481 | AF26: =AE26+$AJ$5*$AJ$4 -> 84.507141 | AG26: =AE26-$AJ$5*$AJ$4 -> 79.203822 | AH26: =AC26-AE26 -> 14.964519 | AL26: Desvio Máximo Anual | AN26: =AN12 -> 9.1820021 | AQ26: Ano com maior volatilidade | BB26: ⭐ DESVIO DIÁRIO RECOMENDADO
A27: =DATEVALUE(Sheet1!A26) -> 44596 | B27: =VALUE(Sheet1!B26) -> 97.13 | C27: =(B27-B26)/B26 -> 0.0032018178 | D27: =MAX(D26,B27) -> 98.33 | E27: =(B27-D27)/D27 -> -0.012203804 | G27: 2022-S24 | H27: =B118 -> 87.42 | I27: =(H27-H26)/H26 -> 0.023533544 | J27: =MAX(J26,H27) -> 103.9 | K27: =(H27-J27)/J27 -> -0.15861405 | M27: jan/2024 | N27: =B523 -> 61.45 | O27: =(N27-N26)/N26 -> -0.11212253 | P27: =MAX(P26,N27) -> 97.4 | Q27: =(N27-P27)/P27 -> -0.36909651 | S27: RESUMO ESTATÍSTICO - MENSAL | AB27: =A27 -> 44596 | AC27: =B27 -> 97.13 | AD27: =25 -> 25 | AE27: =INTERCEPT($AC$3:$AC$1136,$AD$3:$AD$1136)+SLOPE($AC$3:$AC$1136,$AD$3:$AD$1136)*AD27 -> 81.836769 | AF27: =AE27+$AJ$5*$AJ$4 -> 84.488429 | AG27: =AE27-$AJ$5*$AJ$4 -> 79.18511 | AH27: =AC27-AE27 -> 15.293231 | AL27: Amplitude (Max - Min) | AN27: =AN26-AN25 -> 7.3329654 | AQ27: Variação entre anos | BB27: Desvio σ Diário: | BD27: =BC14 -> 0.0063001557
A28: =DATEVALUE(Sheet1!A27) -> 44599 | B28: =VALUE(Sheet1!B27) -> 96.97 | C28: =(B28-B27)/B27 -> -0.0016472768 | D28: =MAX(D27,B28) -> 98.33 | E28: =(B28-D28)/D28 -> -0.013830977 | G28: 2022-S25 | H28: =B123 -> 84.75 | I28: =(H28-H27)/H27 -> -0.03054221 | J28: =MAX(J27,H28) -> 103.9 | K28: =(H28-J28)/J28 -> -0.18431184 | M28: fev/2024 | N28: =B542 -> 62.72 | O28: =(N28-N27)/N27 -> 0.020667209 | P28: =MAX(P27,N28) -> 97.4 | Q28: =(N28-P28)/P28 -> -0.35605749 | S28: Métrica | T28: Valor | AB28: =A28 -> 44599 | AC28: =B28 -> 96.97 | AD28: =26 -> 26 | AE28: =INTERCEPT($AC$3:$AC$1136,$AD$3:$AD$1136)+SLOPE($AC$3:$AC$1136,$AD$3:$AD$1136)*AD28 -> 81.818057 | AF28: =AE28+$AJ$5*$AJ$4 -> 84.469717 | AG28: =AE28-$AJ$5*$AJ$4 -> 79.166398 | AH28: =AC28-AE28 -> 15.151943 | BB28: Multiplicador: | BD28: 2
A29: =DATEVALUE(Sheet1!A28) -> 44600 | B29: =VALUE(Sheet1!B28) -> 97.14 | C29: =(B29-B28)/B28 -> 0.0017531195 | D29: =MAX(D28,B29) -> 98.33 | E29: =(B29-D29)/D29 -> -0.012102105 | G29: 2022-S26 | H29: =B128 -> 83.24 | I29: =(H29-H28)/H28 -> -0.017817109 | J29: =MAX(J28,H29) -> 103.9 | K29: =(H29-J29)/J29 -> -0.19884504 | M29: mar/2024 | N29: =B562 -> 61.71 | O29: =(N29-N28)/N28 -> -0.016103316 | P29: =MAX(P28,N29) -> 97.4 | Q29: =(N29-P29)/P29 -> -0.3664271 | S29: Média Variação | T29: =AVERAGE(O4:O57) -> -0.0054346472 | AB29: =A29 -> 44600 | AC29: =B29 -> 97.14 | AD29: =27 -> 27 | AE29: =INTERCEPT($AC$3:$AC$1136,$AD$3:$AD$1136)+SLOPE($AC$3:$AC$1136,$AD$3:$AD$1136)*AD29 -> 81.799345 | AF29: =AE29+$AJ$5*$AJ$4 -> 84.451005 | AG29: =AE29-$AJ$5*$AJ$4 -> 79.147686 | AH29: =AC29-AE29 -> 15.340655 | AL29: 📊 DESVIO RECOMENDADO | AN29: =AP12 -> 4.8011232 | AQ29: Baseado na média dos anos individuais | BB29: Banda Diária: | BD29: =BD27*BD28 -> 0.012600311
A30: =DATEVALUE(Sheet1!A29) -> 44601 | B30: =VALUE(Sheet1!B29) -> 96.93 | C30: =(B30-B29)/B29 -> -0.0021618283 | D30: =MAX(D29,B30) -> 98.33 | E30: =(B30-D30)/D30 -> -0.014237771 | G30: 2022-S27 | H30: =B133 -> 82.36 | I30: =(H30-H29)/H29 -> -0.01057184 | J30: =MAX(J29,H30) -> 103.9 | K30: =(H30-J30)/J30 -> -0.20731473 | M30: abr/2024 | N30: =B583 -> 57.93 | O30: =(N30-N29)/N29 -> -0.061254254 | P30: =MAX(P29,N30) -> 97.4 | Q30: =(N30-P30)/P30 -> -0.40523614 | S30: Desvio Padrão (σ) | T30: =_xlfn.STDEV.P(O4:O57) -> 0.062699511 | AB30: =A30 -> 44601 | AC30: =B30 -> 96.93 | AD30: =28 -> 28 | AE30: =INTERCEPT($AC$3:$AC$1136,$AD$3:$AD$1136)+SLOPE($AC$3:$AC$1136,$AD$3:$AD$1136)*AD30 -> 81.780633 | AF30: =AE30+$AJ$5*$AJ$4 -> 84.432293 | AG30: =AE30-$AJ$5*$AJ$4 -> 79.128974 | AH30: =AC30-AE30 -> 15.149367 | AL30: Justificativa | AQ30: O desvio médio anual captura melhor a volatilidade típica de cada ano, sem ser inflado pela tendência de longo prazo | BB30: Cobertura Esperada: | BD30: =BK14 -> 0.9303351
A31: =DATEVALUE(Sheet1!A30) -> 44602 | B31: =VALUE(Sheet1!B30) -> 97.08 | C31: =(B31-B30)/B30 -> 0.0015475085 | D31: =MAX(D30,B31) -> 98.33 | E31: =(B31-D31)/D31 -> -0.012712295 | G31: 2022-S28 | H31: =B138 -> 82.36 | I31: =(H31-H30)/H30 -> 0 | J31: =MAX(J30,H31) -> 103.9 | K31: =(H31-J31)/J31 -> -0.20731473 | M31: mai/2024 | N31: =B604 -> 59.36 | O31: =(N31-N30)/N30 -> 0.024684965 | P31: =MAX(P30,N31) -> 97.4 | Q31: =(N31-P31)/P31 -> -0.39055441 | S31: Média - 1σ | T31: =T29-T30 -> -0.068134158 | AB31: =A31 -> 44602 | AC31: =B31 -> 97.08 | AD31: =29 -> 29 | AE31: =INTERCEPT($AC$3:$AC$1136,$AD$3:$AD$1136)+SLOPE($AC$3:$AC$1136,$AD$3:$AD$1136)*AD31 -> 81.761921 | AF31: =AE31+$AJ$5*$AJ$4 -> 84.413581 | AG31: =AE31-$AJ$5*$AJ$4 -> 79.110262 | AH31: =AC31-AE31 -> 15.318079 | BB31: Justificativa: | BD31: Usar σ médio anual (0.63%) com multiplicador 2x = banda de ±1.26%. Cobertura real de ~93% (muito próximo do teórico 95.5%)
A32: =DATEVALUE(Sheet1!A31) -> 44603 | B32: =VALUE(Sheet1!B31) -> 97.05 | C32: =(B32-B31)/B31 -> -0.00030902349 | D32: =MAX(D31,B32) -> 98.33 | E32: =(B32-D32)/D32 -> -0.01301739 | G32: 2022-S29 | H32: =B143 -> 80.2 | I32: =(H32-H31)/H31 -> -0.026226323 | J32: =MAX(J31,H32) -> 103.9 | K32: =(H32-J32)/J32 -> -0.22810395 | M32: jun/2024 | N32: =B625 -> 57.32 | O32: =(N32-N31)/N31 -> -0.034366577 | P32: =MAX(P31,N32) -> 97.4 | Q32: =(N32-P32)/P32 -> -0.41149897 | S32: Média + 1σ | T32: =T29+T30 -> 0.057264864 | AB32: =A32 -> 44603 | AC32: =B32 -> 97.05 | AD32: =30 -> 30 | AE32: =INTERCEPT($AC$3:$AC$1136,$AD$3:$AD$1136)+SLOPE($AC$3:$AC$1136,$AD$3:$AD$1136)*AD32 -> 81.743209 | AF32: =AE32+$AJ$5*$AJ$4 -> 84.394869 | AG32: =AE32-$AJ$5*$AJ$4 -> 79.09155 | AH32: =AC32-AE32 -> 15.306791 | AL32: ANÁLISE DE COBERTURA - DIAS DENTRO DO CANAL POR MULTIPLICADOR
A33: =DATEVALUE(Sheet1!A32) -> 44606 | B33: =VALUE(Sheet1!B32) -> 95.98 | C33: =(B33-B32)/B32 -> -0.011025245 | D33: =MAX(D32,B33) -> 98.33 | E33: =(B33-D33)/D33 -> -0.023899115 | G33: 2022-S30 | H33: =B148 -> 82.64 | I33: =(H33-H32)/H32 -> 0.03042394 | J33: =MAX(J32,H33) -> 103.9 | K33: =(H33-J33)/J33 -> -0.20461983 | M33: jul/2024 | N33: =B648 -> 59.44 | O33: =(N33-N32)/N32 -> 0.036985345 | P33: =MAX(P32,N33) -> 97.4 | Q33: =(N33-P33)/P33 -> -0.38973306 | S33: Média - 2σ | T33: =T29-2*T30 -> -0.13083367 | AB33: =A33 -> 44606 | AC33: =B33 -> 95.98 | AD33: =31 -> 31 | AE33: =INTERCEPT($AC$3:$AC$1136,$AD$3:$AD$1136)+SLOPE($AC$3:$AC$1136,$AD$3:$AD$1136)*AD33 -> 81.724497 | AF33: =AE33+$AJ$5*$AJ$4 -> 84.376157 | AG33: =AE33-$AJ$5*$AJ$4 -> 79.072838 | AH33: =AC33-AE33 -> 14.255503 | AL33: Multiplicador | AM33: Banda (R$) | AN33: 2022 (%) | AO33: 2023 (%) | AP33: 2024 (%) | AQ33: 2025 (%) | AR33: 2026 (%) | AS33: Total (%) | AT33: Média Anos | AU33: Teórico Normal | AV33: Diferença | BB33: COMPARATIVO: DESVIO DIÁRIO vs DESVIO REGRESSÃO
